Workbook

Sheet README
B2: AI Munim, with Intent Guard: 8-quarter GMV and contribution projection (v2, clubhouse pricing)
B3: Paytm Build for India AI Hackathon, Mumbai | Track 1: Merchant Growth AI | Kamalika Poddar
B5: What this model does
B6: 1. Baseline: Paytm merchant GMV and device merchants, projected with FORECAST (linear) on 8 reported quarters, Q2 FY25 to Q1 FY27. GROWTH (exponential) is shown alongside as a cross-check.
B7: 2. AI Munim: an AI munim in the Paytm for Business app. Built for owners of 2-5 outlets, open to every merchant from one shop to a chain. It reads Paytm collections per outlet, bank statements and GST returns through the Account Aggregator (PPSL as FIU) and cash expenses logged by voice. It gives profit per outlet, a 90-day cash plan and shift checks, and acts only inside the owner's mandate (Intent Guard).
B8: 3. Pricing, the clubhouse: a monthly membership per business that includes the first 5 outlets; per-outlet add-ons in slabs above that (outlets 6-10, 11-20, 21+); and utility fees: a shift-check pass per outlet and a CA pack per business. Billed on its own in the Business app, with a notice before every charge. Not bundled with the Soundbox.
B9: 4. Capital tab: pre-approved lines from lending partners, open to every merchant, member or not. Lenders pay Paytm; merchants pay Paytm nothing for credit. Only drawdowns prompted by a member's cash plan are counted here; the rest is Paytm's existing lending.
B10: 5. Businesses are modelled in four size bands (1 outlet, 2-5, 6-20, 21+), each with its own share of device merchants, outlets and adoption.
B11: 6. Outputs: incremental GMV and contribution for 8 quarters from Q4 FY27 (Jan-Mar 2027 Mumbai pilot) to Q3 FY29, in three scenarios (Bear, Base, Bull).
B13: How to use it
B14: Change blue cells on Assumptions (and reported actuals on Baseline). Every other number is a formula and recalculates.
B15: Colour code: blue text = input | black text = formula | green text = link to another sheet | yellow fill = key assumption.
... B38: Caveat: reported figures come from Paytm's disclosures, regulators and press coverage (see Sources). Everything else on Assumptions is a team estimate for a hackathon pitch, not Paytm data. Paytm's own data (PANs by number of outlet IDs, device churn, lending take rates, enterprise book) would replace several estimates directly.

Sheet Assumptions
A1: Assumptions: AI Munim, with Intent Guard (v2, clubhouse pricing)
A2: Blue cells are inputs. Bear / Base / Bull columns feed the three scenario blocks on the Model sheet. Team estimates unless a source is named (Sources sheet). Prices are per month, excluding GST.
A4: ID | B4: Assumption | C4: Unit | D4: Bear | E4: Base | F4: Bull | L4: Why this number / source
A5: Common
A6: K1 | B6: Payment processing margin on incremental GMV | C6: % of GMV | D6: 0.0004 | E6: 0.0004 | F6: 0.0004 | L6: Paytm Q1 FY27: payment processing margin 'comfortably above 4 bps' (S1, S10). Held at 4 bps in all scenarios.
A7: K2 | B7: Paytm-processed GMV per outlet, multi-outlet members, before the Munim | C7: Rs / month | D7: 60000 | E7: 90000 | F7: 130000 | L7: Team estimate: outlets of multi-outlet businesses run busier counters than the average device merchant. Ceiling check on Baseline: ~Rs 1.5 lakh a month if all GMV came from device merchants.
A8: K3 | B8: Paytm-processed GMV of a single-outlet member, before the Munim | C8: Rs / month | D8: 30000 | E8: 45000 | F8: 60000 | L8: Team estimate: below the multi-outlet figure and well under the ~Rs 1.5 lakh ceiling.
A9: K4 | B9: Device subscription revenue per outlet | C9: Rs / month | D9: 80 | E9: 90 | F9: 100 | L9: ~Rs 90 per device a month in Q4 FY24 (S8); the Q1 FY27 release notes a modest YoY decline per device (S1).
A10: Who could join: businesses by size, as a share of device merchants
A11: S1 | B11: Single-outlet businesses | C11: % of device merchants | D11: 0.65 | E11: 0.7 | F11: 0.75 | L11: Team estimate. The rest of the count is multi-outlet businesses and second devices at the same counter (check on Summary).
A12: S2 | B12: Businesses running 2-5 outlets | C12: % of device merchants | D12: 0.02 | E12: 0.04 | F12: 0.06 | L12: Team estimate. At base, 4 businesses per 100 device merchants x 2.5 outlets = about 10 of every 100 devices. Paytm can replace this with its count of PANs with 2-5 outlet IDs.
A13: S3 | B13: Businesses running 6-20 outlets | C13: % of device merchants | D13: 0.001 | E13: 0.002 | F13: 0.003 | L13: Team estimate: small chains.
A14: S4 | B14: Businesses running 21 or more outlets (enterprise) | C14: % of device merchants | D14: 5e-05 | E14: 0.0001 | F14: 0.00015 | L14: Team estimate: about 2,200 chains at base by Q3 FY29. Paytm's enterprise book would replace this.
A15: S5 | B15: Average outlets, 2-5 band | C15: outlets | D15: 2.3 | E15: 2.5 | F15: 2.8 | L15: Team estimate.
A16: S6 | B16: Average outlets, 6-20 band | C16: outlets | D16: 8 | E16: 10 | F16: 12 | L16: Team estimate.
A17: S7 | B17: Average outlets, 21+ band | C17: outlets | D17: 60 | E17: 100 | F17: 150 | L17: Team estimate.
A18: Who pays: paying members as a share of businesses reached
A19: A1 | B19: Single-outlet businesses | C19: % of reached | D19: 0.005 | E19: 0.01 | F19: 0.02 | L19: Team estimate. A single shop gets less from the Munim (most owners run their own counter), so few pay. Reached in the app at little cost.
A20: A2 | B20: 2-5 outlet businesses | C20: % of reached | D20: 0.05 | E20: 0.1 | F20: 0.15 | L20: Team estimate, unchanged from the flat-price version even though this band now pays less (an upside we don't count). Paid from day one; no free tier.
A21: A3 | B21: 6-20 outlet businesses | C21: % of reached | D21: 0.04 | E21: 0.08 | F21: 0.12 | L21: Team estimate.
A22: A4 | B22: 21+ outlet businesses (enterprise) | C22: % of reached | D22: 0.01 | E22: 0.03 | F22: 0.06 | L22: Team estimate. Enterprise deals are sales-led and slow; many chains already run an ERP.
A23: A5 | B23: Extra outlets opened per 100 paying businesses per year (cash plan and credit) | C23: per 100 / year | D23: 1 | E23: 2 | F23: 4 | L23: Team estimate. New outlets come onto a Paytm device and the Munim.
A24: Pricing: the clubhouse (per month, excluding GST)
A25: P1 | B25: Membership per business, includes the first 5 outlets | C25: Rs / month | D25: 149 | E25: 199 | F25: 299 | L25: The membership: outlet view, staff roles, profit per outlet, 90-day cash plan, Intent Guard, evidence log. Anchors: the earlier flat price of Rs 199 per outlet; Soundbox rental runs Rs 125-150 (S7).
A26: P2 | B26: Add-on per outlet, outlets 6-10 | C26: Rs / outlet / month | D26: 29 | E26: 49 | F26: 79 | L26: Kept small so the step after 5 included outlets is gentle.
A27: P3 | B27: Add-on per outlet, outlets 11-20 | C27: Rs / outlet / month | D27: 49 | E27: 79 | F27: 99 | L27: Team estimate.
A28: P4 | B28: Add-on per outlet, outlets 21 and above | C28: Rs / outlet / month | D28: 69 | E28: 99 | F28: 149 | L28: List price. Chains this size will negotiate.
A29: P5 | B29: Shift-check pass, per outlet | C29: Rs / outlet / month | D29: 79 | E29: 99 | F29: 149 | L29: Utility fee, unlimited checks. Priced above its own AI and photo-check cost.
A30: P6 | B30: Pass uptake, single-outlet members | C30: % of outlets | D30: 0.05 | E30: 0.1 | F30: 0.2 | L30: Team estimate: most single shops are run by the owner.
A31: P7 | B31: Pass uptake, multi-outlet members | C31: % of outlets | D31: 0.3 | E31: 0.5 | F31: 0.7 | L31: Team estimate: staffed counters are where shift checks matter.
A32: P8 | B32: CA pack, per business | C32: Rs / month | D32: 79 | E32: 99 | F32: 149 | L32: Utility fee: a books-ready monthly pack (charges by payment type, GST for input credit) for the business's CA.
A33: P9 | B33: CA pack uptake | C33: % of members | D33: 0.1 | E33: 0.2 | F33: 0.3 | L33: Team estimate.
A34: Capital tab: open to every merchant; only drawdowns prompted by a member's cash plan are counted
A35: C1 | B35: Members with a pre-approved line (1-20 outlets; chains of 21+ use their bank limits) | C35: % of members | D35: 0.3 | E35: 0.45 | F35: 0.6 | L35: The lender takes its own AA consent and runs its rules engine upfront. Benchmark: public-sector banks' digital MSME model approved ~47% of applications in Apr-Oct FY26 (S12).
A36: C2 | B36: Drawdowns per year per member with a line | C36: per year | D36: 1.5 | E36: 2 | F36: 3 | L36: Team estimate: festive stock-ups, wedding season, a new outlet.
A37: C3 | B37: Average drawdown, per outlet of the business | C37: Rs per outlet | D37: 40000 | E37: 80000 | F37: 120000 | L37: Team estimate: Rs 2 lakh for a 2.5-outlet business at base, as in v1. Paytm business loans run up to Rs 10 lakh over 3-36 months (S29).
A38: C4 | B38: Paytm revenue per drawdown (distribution and collection support), paid by the lender | C38: % of drawdown | D38: 0.015 | E38: 0.02 | F38: 0.025 | L38: Team estimate. Paytm doesn't publish take rates. Under RBI's digital lending rules the lender pays this, never the borrower (S30).
A39: C5 | B39: Collection and servicing per drawdown (reminders, repayment follow-up) | C39: % of drawdown | D39: 0.005 | E39: 0.003 | F39: 0.002 | L39: Team estimate. The support Paytm is paid for (C4) has its own cost.
A40: C6 | B40: Paytm credit-loss sharing | C40: % of drawdown | D40: 0.0075 | E40: 0.004 | F40: 0 | L40: Team estimate. RBI caps default-loss guarantees at 5% of a loan portfolio (S26); whether Paytm offers one isn't public.
A41: Growth levers (applied to the Paytm GMV of member outlets)
...

Sheet Baseline
A1: Baseline: Paytm merchant GMV and device merchants
A2: Rows 5-12 are reported actuals (blue). Rows 13-22 are FORECAST (linear) on those 8 quarters. Column G is GROWTH (exponential) as a cross-check. The model uses the linear forecast.
A4: x (period) | B4: Quarter | C4: Months | D4: Type | E4: Merchant GMV (Rs lakh crore) | F4: GMV YoY | G4: Cross-check: GROWTH (Rs lakh crore) | H4: Device merchants (crore) | I4: Source / method
A5: 1 | B5: Q2 FY25 | C5: Jul-Sep 2024 | D5: Actual | E5: 4.5 | H5: 1.12 | I5: GMV: S5 (Q3 FY25 GMV up 13% QoQ from Rs 4.5 lakh crore). Device merchants: derived, 1.17 crore at Dec-24 minus 5 lakh added that quarter (S5).
A6: 2 | B6: Q3 FY25 | C6: Oct-Dec 2024 | D6: Actual | E6: 5 | H6: 1.17 | I6: S5
A7: 3 | B7: Q4 FY25 | C7: Jan-Mar 2025 | D7: Actual | E7: 5.1 | H7: 1.24 | I7: S4
A8: 4 | B8: Q1 FY26 | C8: Apr-Jun 2025 | D8: Actual | E8: 5.4 | H8: 1.3 | I8: S1 (Jun-25 column of the Q1 FY27 release)
A9: 5 | B9: Q2 FY26 | C9: Jul-Sep 2025 | D9: Actual | E9: 5.67 | F9: =E9/E5-1 -> 0.26 | H9: 1.37 | I9: S2
A10: 6 | B10: Q3 FY26 | C10: Oct-Dec 2025 | D10: Actual | E10: 6.2 | F10: =E10/E6-1 -> 0.24 | H10: 1.44 | I10: GMV: S3. Device merchants: S6
A11: 7 | B11: Q4 FY26 | C11: Jan-Mar 2026 | D11: Actual | E11: 6.5 | F11: =E11/E7-1 -> 0.2745098 | H11: 1.51 | I11: S1 (Mar-26 column)
A12: 8 | B12: Q1 FY27 | C12: Apr-Jun 2026 | D12: Actual | E12: 7.1 | F12: =E12/E8-1 -> 0.31481481 | H12: 1.57 | I12: S1, S10
A13: 9 | B13: Q2 FY27 | C13: Jul-Sep 2026 | D13: Forecast | E13: =FORECAST(A13,$E$5:$E$12,$A$5:$A$12) -> 7.2517857 | F13: =E13/E9-1 -> 0.27897455 | G13: =GROWTH($E$5:$E$12,$A$5:$A$12,A13) -> 7.4103976 | H13: =FORECAST(A13,$H$5:$H$12,$A$5:$A$12) -> 1.6357143 | I13: FORECAST (linear) on rows 5-12. Not yet reported; bridges to the projection window.
A14: 10 | B14: Q3 FY27 | C14: Oct-Dec 2026 | D14: Forecast | E14: =FORECAST(A14,$E$5:$E$12,$A$5:$A$12) -> 7.6002381 | F14: =E14/E10-1 -> 0.22584485 | G14: =GROWTH($E$5:$E$12,$A$5:$A$12,A14) -> 7.8778783 | H14: =FORECAST(A14,$H$5:$H$12,$A$5:$A$12) -> 1.7014286 | I14: FORECAST (linear) on rows 5-12. Not yet reported; bridges to the projection window.
A15: 11 | B15: Q4 FY27 | C15: Jan-Mar 2027 | D15: Forecast | E15: =FORECAST(A15,$E$5:$E$12,$A$5:$A$12) -> 7.9486905 | F15: =E15/E11-1 -> 0.22287546 | G15: =GROWTH($E$5:$E$12,$A$5:$A$12,A15) -> 8.3748497 | H15: =FORECAST(A15,$H$5:$H$12,$A$5:$A$12) -> 1.7671429 | I15: FORECAST (linear) on rows 5-12
A16: 12 | B16: Q1 FY28 | C16: Apr-Jun 2027 | D16: Forecast | E16: =FORECAST(A16,$E$5:$E$12,$A$5:$A$12) -> 8.2971429 | F16: =E16/E12-1 -> 0.16861167 | G16: =GROWTH($E$5:$E$12,$A$5:$A$12,A16) -> 8.9031723 | H16: =FORECAST(A16,$H$5:$H$12,$A$5:$A$12) -> 1.8328571 | I16: FORECAST (linear) on rows 5-12
A17: 13 | B17: Q2 FY28 | C17: Jul-Sep 2027 | D17: Forecast | E17: =FORECAST(A17,$E$5:$E$12,$A$5:$A$12) -> 8.6455952 | F17: =E17/E13-1 -> 0.19220225 | G17: =GROWTH($E$5:$E$12,$A$5:$A$12,A17) -> 9.4648238 | H17: =FORECAST(A17,$H$5:$H$12,$A$5:$A$12) -> 1.8985714 | I17: FORECAST (linear) on rows 5-12
A18: 14 | B18: Q3 FY28 | C18: Oct-Dec 2027 | D18: Forecast | E18: =FORECAST(A18,$E$5:$E$12,$A$5:$A$12) -> 8.9940476 | F18: =E18/E14-1 -> 0.18339024 | G18: =GROWTH($E$5:$E$12,$A$5:$A$12,A18) -> 10.061907 | H18: =FORECAST(A18,$H$5:$H$12,$A$5:$A$12) -> 1.9642857 | I18: FORECAST (linear) on rows 5-12
A19: 15 | B19: Q4 FY28 | C19: Jan-Mar 2028 | D19: Forecast | E19: =FORECAST(A19,$E$5:$E$12,$A$5:$A$12) -> 9.3425 | F19: =E19/E15-1 -> 0.17535084 | G19: =GROWTH($E$5:$E$12,$A$5:$A$12,A19) -> 10.696656 | H19: =FORECAST(A19,$H$5:$H$12,$A$5:$A$12) -> 2.03 | I19: FORECAST (linear) on rows 5-12
A20: 16 | B20: Q1 FY29 | C20: Apr-Jun 2028 | D20: Forecast | E20: =FORECAST(A20,$E$5:$E$12,$A$5:$A$12) -> 9.6909524 | F20: =E20/E16-1 -> 0.16798669 | G20: =GROWTH($E$5:$E$12,$A$5:$A$12,A20) -> 11.371449 | H20: =FORECAST(A20,$H$5:$H$12,$A$5:$A$12) -> 2.0957143 | I20: FORECAST (linear) on rows 5-12
A21: 17 | B21: Q2 FY29 | C21: Jul-Sep 2028 | D21: Forecast | E21: =FORECAST(A21,$E$5:$E$12,$A$5:$A$12) -> 10.039405 | F21: =E21/E17-1 -> 0.16121614 | G21: =GROWTH($E$5:$E$12,$A$5:$A$12,A21) -> 12.08881 | H21: =FORECAST(A21,$H$5:$H$12,$A$5:$A$12) -> 2.1614286 | I21: FORECAST (linear) on rows 5-12
A22: 18 | B22: Q3 FY29 | C22: Oct-Dec 2028 | D22: Forecast | E22: =FORECAST(A22,$E$5:$E$12,$A$5:$A$12) -> 10.387857 | F22: =E22/E18-1 -> 0.15497022 | G22: =GROWTH($E$5:$E$12,$A$5:$A$12,A22) -> 12.851426 | H22: =FORECAST(A22,$H$5:$H$12,$A$5:$A$12) -> 2.2271429 | I22: FORECAST (linear) on rows 5-12
A25: Reported reference points (Q1 FY27, quarter ended 30 June 2026), checks, earlier versions and options
B26: Revenue from operations | D26: Rs crore | F26: 2448 | I26: S10 (up 28% YoY)
B27: Contribution profit | D27: Rs crore | F27: 1350 | I27: S10 (up 17% YoY)
B28: Contribution margin | D28: % of revenue | F28: 0.55 | I28: S10
B29: EBITDA | D29: Rs crore | F29: 203 | I29: S10 (8% margin)
B30: Profit after tax | D30: Rs crore | F30: 220 | I30: S10 (up 79% YoY)
B31: Financial services revenue (merchant loans, personal loans, insurance distribution) | D31: Rs crore | F31: 814 | I31: S10 (up 45% YoY)
B32: Net payment revenue, excluding PIDF | D32: Rs crore | F32: 601 | I32: S1, S10
B33: Net payment revenue per Rs of GMV | D33: bps | F33: =F32/(E12*100000)*10000 -> 8.4647887 | I33: Formula. Paytm reports 8.4 bps (S1).
B34: Ceiling: GMV per device merchant per month if all GMV came from device merchants | D34: Rs / month | F34: =E12*1000000000000/(H12*10000000)/3 -> 150743.1 | I34: Formula. Upper bound used to sanity-check K2 and K3.
B35: Q3 FY29 baseline: GROWTH cross-check vs FORECAST | D35: % above linear | F35: =G22/E22-1 -> 0.2371585 | I35: Formula. How conservative the linear baseline is.
B36: Previous version of this model (flat Rs 199 per outlet, 2-5 outlet businesses only): base contribution over the same 8 quarters | D36: Rs crore | F36: 45.87 | I36: AI_Munim_Projection.xlsx v1, Summary, base case.
B37: Previous version of this model: base incremental GMV over the same 8 quarters | D37: Rs crore | F37: 1792.07 | I37: AI_Munim_Projection.xlsx v1, Summary, base case.
B38: Earlier option, dropped: Mohalla Network, base contribution over the same 8 quarters | D38: Rs crore | F38: 29.52 | I38: Mohalla_GMV_Projection.xlsx, Summary, base case.
B39: Earlier option, parked: Restock Agent, base contribution over the same 8 quarters | D39: Rs crore | F39: 26.22 | I39: Restock_Care_Projection.xlsx, Summary, base case.
B40: Earlier option, parked: Restock Agent, supplier payments new to Paytm over the same 8 quarters | D40: Rs crore | F40: 20419.56 | I40: Restock_Care_Projection.xlsx, Summary, base case (5.35 lakh active grocery shops).
B41: Earlier option, folded in: Soundbox Care, base contribution over the same 8 quarters | D41: Rs crore | F41: 70.01 | I41: Restock_Care_Projection.xlsx, Summary, base case (mostly Paytm's own device-service savings).

Sheet Model
A1: Model: AI Munim, with Intent Guard, quarter by quarter, by business size
A2: Every cell is a formula. Assumption references: Bear = Assumptions column D, Base = E, Bull = F. Column L sums flows over the 8 quarters; stock rows show Q3 FY29; ratio rows divide the 8-quarter totals.
A4: # | B4: Quarter | C4: Unit | D4: Q4 FY27 | E4: Q1 FY28 | F4: Q2 FY28 | G4: Q3 FY28 | H4: Q4 FY28 | I4: Q1 FY29 | J4: Q2 FY29 | K4: Q3 FY29 | L4: 8-qtr total
B5: Months | D5: Jan-Mar 2027 | E5: Apr-Jun 2027 | F5: Jul-Sep 2027 | G5: Oct-Dec 2027 | H5: Jan-Mar 2028 | I5: Apr-Jun 2028 | J5: Jul-Sep 2028 | K5: Oct-Dec 2028
B6: Baseline period index (x) | D6: =Baseline!A15 -> 11 | E6: =Baseline!A16 -> 12 | F6: =Baseline!A17 -> 13 | G6: =Baseline!A18 -> 14 | H6: =Baseline!A19 -> 15 | I6: =Baseline!A20 -> 16 | J6: =Baseline!A21 -> 17 | K6: =Baseline!A22 -> 18
A8: BEAR scenario (Assumptions column D)
B9: Device merchants and rollout
A10: 1 | B10: Device merchants, baseline | C10: lakh | D10: =Baseline!H15*100 -> 176.71429 | E10: =Baseline!H16*100 -> 183.28571 | F10: =Baseline!H17*100 -> 189.85714 | G10: =Baseline!H18*100 -> 196.42857 | H10: =Baseline!H19*100 -> 203 | I10: =Baseline!H20*100 -> 209.57143 | J10: =Baseline!H21*100 -> 216.14286 | K10: =Baseline!H22*100 -> 222.71429 | L10: =K10 -> 222.71429
A11: 2 | B11: Share of businesses reached (rollout) | C11: % of businesses | D11: =Assumptions!D$63 -> 0.05 | E11: =Assumptions!E$63 -> 0.15 | F11: =Assumptions!F$63 -> 0.3 | G11: =Assumptions!G$63 -> 0.45 | H11: =Assumptions!H$63 -> 0.6 | I11: =Assumptions!I$63 -> 0.7 | J11: =Assumptions!J$63 -> 0.8 | K11: =Assumptions!K$63 -> 0.85 | L11: =K11 -> 0.85
B12: Band 1: Single-outlet businesses
A13: 3 | B13: Businesses in this band | C13: lakh | D13: =D10*Assumptions!$D$11 -> 114.86429 | E13: =E10*Assumptions!$D$11 -> 119.13571 | F13: =F10*Assumptions!$D$11 -> 123.40714 | G13: =G10*Assumptions!$D$11 -> 127.67857 | H13: =H10*Assumptions!$D$11 -> 131.95 | I13: =I10*Assumptions!$D$11 -> 136.22143 | J13: =J10*Assumptions!$D$11 -> 140.49286 | K13: =K10*Assumptions!$D$11 -> 144.76429 | L13: =K13 -> 144.76429
A14: 4 | B14: Paying members | C14: lakh | D14: =D13*D11*Assumptions!$D$19 -> 0.028716071 | E14: =E13*E11*Assumptions!$D$19 -> 0.089351786 | F14: =F13*F11*Assumptions!$D$19 -> 0.18511071 | G14: =G13*G11*Assumptions!$D$19 -> 0.28727679 | H14: =H13*H11*Assumptions!$D$19 -> 0.39585 | I14: =I13*I11*Assumptions!$D$19 -> 0.476775 | J14: =J13*J11*Assumptions!$D$19 -> 0.56197143 | K14: =K13*K11*Assumptions!$D$19 -> 0.61524821 | L14: =K14 -> 0.61524821
A15: 5 | B15: New paying members | C15: lakh | D15: =MAX(0,D14-N(C14)) -> 0.028716071 | E15: =MAX(0,E14-N(D14)) -> 0.060635714 | F15: =MAX(0,F14-N(E14)) -> 0.095758929 | G15: =MAX(0,G14-N(F14)) -> 0.10216607 | H15: =MAX(0,H14-N(G14)) -> 0.10857321 | I15: =MAX(0,I14-N(H14)) -> 0.080925 | J15: =MAX(0,J14-N(I14)) -> 0.085196429 | K15: =MAX(0,K14-N(J14)) -> 0.053276786 | L15: =SUM(D15:K15) -> 0.61524821
A16: 6 | B16: Member outlets | C16: lakh | D16: =D14*1 -> 0.028716071 | E16: =E14*1 -> 0.089351786 | F16: =F14*1 -> 0.18511071 | G16: =G14*1 -> 0.28727679 | H16: =H14*1 -> 0.39585 | I16: =I14*1 -> 0.476775 | J16: =J14*1 -> 0.56197143 | K16: =K14*1 -> 0.61524821 | L16: =K16 -> 0.61524821
A17: 7 | B17: Extra outlets opened (cumulative) | C17: lakh | D17: =N(C17)+D14*Assumptions!$D$23/100/4 -> 7.1790179e-05 | E17: =N(D17)+E14*Assumptions!$D$23/100/4 -> 0.00029516964 | F17: =N(E17)+F14*Assumptions!$D$23/100/4 -> 0.00075794643 | G17: =N(F17)+G14*Assumptions!$D$23/100/4 -> 0.0014761384 | H17: =N(G17)+H14*Assumptions!$D$23/100/4 -> 0.0024657634 | I17: =N(H17)+I14*Assumptions!$D$23/100/4 -> 0.0036577009 | J17: =N(I17)+J14*Assumptions!$D$23/100/4 -> 0.0050626295 | K17: =N(J17)+K14*Assumptions!$D$23/100/4 -> 0.00660075 | L17: =K17 -> 0.00660075
A18: 8 | B18: Member outlets, including new ones | C18: lakh | D18: =D16+D17 -> 0.028787862 | E18: =E16+E17 -> 0.089646955 | F18: =F16+F17 -> 0.18586866 | G18: =G16+G17 -> 0.28875292 | H18: =H16+H17 -> 0.39831576 | I18: =I16+I17 -> 0.4804327 | J18: =J16+J17 -> 0.56703406 | K18: =K16+K17 -> 0.62184896 | L18: =K18 -> 0.62184896
A19: 9 | B19: Outlets with the shift-check pass | C19: lakh | D19: =D18*Assumptions!$D$30 -> 0.0014393931 | E19: =E18*Assumptions!$D$30 -> 0.0044823478 | F19: =F18*Assumptions!$D$30 -> 0.009293433 | G19: =G18*Assumptions!$D$30 -> 0.014437646 | H19: =H18*Assumptions!$D$30 -> 0.019915788 | I19: =I18*Assumptions!$D$30 -> 0.024021635 | J19: =J18*Assumptions!$D$30 -> 0.028351703 | K19: =K18*Assumptions!$D$30 -> 0.031092448 | L19: =K19 -> 0.031092448
A20: 10 | B20: Members with a pre-approved line | C20: lakh | D20: =D14*Assumptions!$D$35 -> 0.0086148214 | E20: =E14*Assumptions!$D$35 -> 0.026805536 | F20: =F14*Assumptions!$D$35 -> 0.055533214 | G20: =G14*Assumptions!$D$35 -> 0.086183036 | H20: =H14*Assumptions!$D$35 -> 0.118755 | I20: =I14*Assumptions!$D$35 -> 0.1430325 | J20: =J14*Assumptions!$D$35 -> 0.16859143 | K20: =K14*Assumptions!$D$35 -> 0.18457446 | L20: =K20 -> 0.18457446
A21: 11 | B21: Drawdowns prompted by the cash plan | C21: lakh | D21: =D20*Assumptions!$D$36/4 -> 0.003230558 | E21: =E20*Assumptions!$D$36/4 -> 0.010052076 | F21: =F20*Assumptions!$D$36/4 -> 0.020824955 | G21: =G20*Assumptions!$D$36/4 -> 0.032318638 | H21: =H20*Assumptions!$D$36/4 -> 0.044533125 | I21: =I20*Assumptions!$D$36/4 -> 0.053637188 | J21: =J20*Assumptions!$D$36/4 -> 0.063221786 | K21: =K20*Assumptions!$D$36/4 -> 0.069215424 | L21: =SUM(D21:K21) -> 0.29703375
A22: 12 | B22: Drawdown value | C22: Rs crore | D22: =D21*Assumptions!$D$37*1/100 -> 1.2922232 | E22: =E21*Assumptions!$D$37*1/100 -> 4.0208304 | F22: =F21*Assumptions!$D$37*1/100 -> 8.3299821 | G22: =G21*Assumptions!$D$37*1/100 -> 12.927455 | H22: =H21*Assumptions!$D$37*1/100 -> 17.81325 | I22: =I21*Assumptions!$D$37*1/100 -> 21.454875 | J22: =J21*Assumptions!$D$37*1/100 -> 25.288714 | K22: =K21*Assumptions!$D$37*1/100 -> 27.68617 | L22: =SUM(D22:K22) -> 118.8135
A23: 13 | B23: Paytm GMV of member outlets before the Munim (reference) | C23: Rs crore | D23: =D16*Assumptions!$D$8*3/100 -> 25.844464 | E23: =E16*Assumptions!$D$8*3/100 -> 80.416607 | F23: =F16*Assumptions!$D$8*3/100 -> 166.59964 | G23: =G16*Assumptions!$D$8*3/100 -> 258.54911 | H23: =H16*Assumptions!$D$8*3/100 -> 356.265 | I23: =I16*Assumptions!$D$8*3/100 -> 429.0975 | J23: =J16*Assumptions!$D$8*3/100 -> 505.77429 | K23: =K16*Assumptions!$D$8*3/100 -> 553.72339 | L23: =SUM(D23:K23) -> 2376.27
A24: 14 | B24: GMV: extra sales from the cash plan | C24: Rs crore | D24: =D23*Assumptions!$D$42 -> 0.25844464 | E24: =E23*Assumptions!$D$42 -> 0.80416607 | F24: =F23*Assumptions!$D$42 -> 1.6659964 | G24: =G23*Assumptions!$D$42 -> 2.5854911 | H24: =H23*Assumptions!$D$42 -> 3.56265 | I24: =I23*Assumptions!$D$42 -> 4.290975 | J24: =J23*Assumptions!$D$42 -> 5.0577429 | K24: =K23*Assumptions!$D$42 -> 5.5372339 | L24: =SUM(D24:K24) -> 23.7627
A25: 15 | B25: GMV: leakage recovered (outlets with the pass) | C25: Rs crore | D25: =D19*Assumptions!$D$8*3/100*Assumptions!$D$44 -> 0.0064772689 | E25: =E19*Assumptions!$D$8*3/100*Assumptions!$D$44 -> 0.020170565 | F25: =F19*Assumptions!$D$8*3/100*Assumptions!$D$44 -> 0.041820449 | G25: =G19*Assumptions!$D$8*3/100*Assumptions!$D$44 -> 0.064969408 | H25: =H19*Assumptions!$D$8*3/100*Assumptions!$D$44 -> 0.089621047 | I25: =I19*Assumptions!$D$8*3/100*Assumptions!$D$44 -> 0.10809736 | J25: =J19*Assumptions!$D$8*3/100*Assumptions!$D$44 -> 0.12758266 | K25: =K19*Assumptions!$D$8*3/100*Assumptions!$D$44 -> 0.13991602 | L25: =SUM(D25:K25) -> 0.59865477
A26: 16 | B26: Outlets kept by lower device churn (cumulative) | C26: lakh | D26: =N(C26)+D18*Assumptions!$D$45/4 -> 7.1969654e-05 | E26: =N(D26)+E18*Assumptions!$D$45/4 -> 0.00029608704 | F26: =N(E26)+F18*Assumptions!$D$45/4 -> 0.00076075869 | G26: =N(F26)+G18*Assumptions!$D$45/4 -> 0.001482641 | H26: =N(G26)+H18*Assumptions!$D$45/4 -> 0.0024784304 | I26: =N(H26)+I18*Assumptions!$D$45/4 -> 0.0036795122 | J26: =N(I26)+J18*Assumptions!$D$45/4 -> 0.0050970973 | K26: =N(J26)+K18*Assumptions!$D$45/4 -> 0.0066517197 | L26: =K26 -> 0.0066517197
A27: 17 | B27: GMV: kept by lower device churn | C27: Rs crore | D27: =D26*Assumptions!$D$8*3/100 -> 0.064772689 | E27: =E26*Assumptions!$D$8*3/100 -> 0.26647834 | F27: =F26*Assumptions!$D$8*3/100 -> 0.68468282 | G27: =G26*Assumptions!$D$8*3/100 -> 1.3343769 | H27: =H26*Assumptions!$D$8*3/100 -> 2.2305874 | I27: =I26*Assumptions!$D$8*3/100 -> 3.3115609 | J27: =J26*Assumptions!$D$8*3/100 -> 4.5873876 | K27: =K26*Assumptions!$D$8*3/100 -> 5.9865477 | L27: =SUM(D27:K27) -> 18.466394
A28: 18 | B28: GMV: extra outlets opened | C28: Rs crore | D28: =D17*Assumptions!$D$8*3/100 -> 0.064611161 | E28: =E17*Assumptions!$D$8*3/100 -> 0.26565268 | F28: =F17*Assumptions!$D$8*3/100 -> 0.68215179 | G28: =G17*Assumptions!$D$8*3/100 -> 1.3285246 | H28: =H17*Assumptions!$D$8*3/100 -> 2.2191871 | I28: =I17*Assumptions!$D$8*3/100 -> 3.2919308 | J28: =J17*Assumptions!$D$8*3/100 -> 4.5563665 | K28: =K17*Assumptions!$D$8*3/100 -> 5.940675 | L28: =SUM(D28:K28) -> 18.3491
A29: 19 | B29: Incremental GMV | C29: Rs crore | D29: =D24+D25+D27+D28 -> 0.39430576 | E29: =E24+E25+E27+E28 -> 1.3564677 | F29: =F24+F25+F27+F28 -> 3.0746515 | G29: =G24+G25+G27+G28 -> 5.3133619 | H29: =H24+H25+H27+H28 -> 8.1020455 | I29: =I24+I25+I27+I28 -> 11.002564 | J29: =J24+J25+J27+J28 -> 14.32908 | K29: =K24+K25+K27+K28 -> 17.604373 | L29: =SUM(D29:K29) -> 61.176849
A30: 20 | B30: Revenue: membership | C30: Rs crore | D30: =D14*Assumptions!$D$25*3/100 -> 0.12836084 | E30: =E14*Assumptions!$D$25*3/100 -> 0.39940248 | F30: =F14*Assumptions!$D$25*3/100 -> 0.82744489 | G30: =G14*Assumptions!$D$25*3/100 -> 1.2841272 | H30: =H14*Assumptions!$D$25*3/100 -> 1.7694495 | I30: =I14*Assumptions!$D$25*3/100 -> 2.1311843 | J30: =J14*Assumptions!$D$25*3/100 -> 2.5120123 | K30: =K14*Assumptions!$D$25*3/100 -> 2.7501595 | L30: =SUM(D30:K30) -> 11.802141
A31: 21 | B31: Revenue: shift-check passes | C31: Rs crore | D31: =D19*Assumptions!$D$29*3/100 -> 0.0034113616 | E31: =E19*Assumptions!$D$29*3/100 -> 0.010623164 | F31: =F19*Assumptions!$D$29*3/100 -> 0.022025436 | G31: =G19*Assumptions!$D$29*3/100 -> 0.034217222 | H31: =H19*Assumptions!$D$29*3/100 -> 0.047200418 | I31: =I19*Assumptions!$D$29*3/100 -> 0.056931275 | J31: =J19*Assumptions!$D$29*3/100 -> 0.067193536 | K31: =K19*Assumptions!$D$29*3/100 -> 0.073689102 | L31: =SUM(D31:K31) -> 0.31529151
A32: 22 | B32: Revenue: CA packs | C32: Rs crore | D32: =D14*Assumptions!$D$33*Assumptions!$D$32*3/100 -> 0.0068057089 | E32: =E14*Assumptions!$D$33*Assumptions!$D$32*3/100 -> 0.021176373 | F32: =F14*Assumptions!$D$33*Assumptions!$D$32*3/100 -> 0.043871239 | G32: =G14*Assumptions!$D$33*Assumptions!$D$32*3/100 -> 0.068084598 | H32: =H14*Assumptions!$D$33*Assumptions!$D$32*3/100 -> 0.09381645 | I32: =I14*Assumptions!$D$33*Assumptions!$D$32*3/100 -> 0.11299568 | J32: =J14*Assumptions!$D$33*Assumptions!$D$32*3/100 -> 0.13318723 | K32: =K14*Assumptions!$D$33*Assumptions!$D$32*3/100 -> 0.14581383 | L32: =SUM(D32:K32) -> 0.6257511
A33: 23 | B33: Revenue: credit (lender pays Paytm a share of each drawdown) | C33: Rs crore | D33: =D22*Assumptions!$D$38 -> 0.019383348 | E33: =E22*Assumptions!$D$38 -> 0.060312455 | F33: =F22*Assumptions!$D$38 -> 0.12494973 | G33: =G22*Assumptions!$D$38 -> 0.19391183 | H33: =H22*Assumptions!$D$38 -> 0.26719875 | I33: =I22*Assumptions!$D$38 -> 0.32182312 | J33: =J22*Assumptions!$D$38 -> 0.37933071 | K33: =K22*Assumptions!$D$38 -> 0.41529254 | L33: =SUM(D33:K33) -> 1.7822025
A34: 24 | B34: Revenue: payment margin on incremental GMV | C34: Rs crore | D34: =D29*Assumptions!$D$6 -> 0.0001577223 | E34: =E29*Assumptions!$D$6 -> 0.00054258706 | F34: =F29*Assumptions!$D$6 -> 0.0012298606 | G34: =G29*Assumptions!$D$6 -> 0.0021253448 | H34: =H29*Assumptions!$D$6 -> 0.0032408182 | I34: =I29*Assumptions!$D$6 -> 0.0044010256 | J34: =J29*Assumptions!$D$6 -> 0.0057316318 | K34: =K29*Assumptions!$D$6 -> 0.0070417491 | L34: =SUM(D34:K34) -> 0.024470739
A35: 25 | B35: Revenue: device subscriptions kept and added | C35: Rs crore | D35: =(D26+D17)*Assumptions!$D$9*3/100 -> 0.0003450236 | E35: =(E26+E17)*Assumptions!$D$9*3/100 -> 0.001419016 | F35: =(F26+F17)*Assumptions!$D$9*3/100 -> 0.0036448923 | G35: =(G26+G17)*Assumptions!$D$9*3/100 -> 0.0071010706 | H35: =(H26+H17)*Assumptions!$D$9*3/100 -> 0.011866065 | I35: =(I26+I17)*Assumptions!$D$9*3/100 -> 0.017609311 | J35: =(J26+J17)*Assumptions!$D$9*3/100 -> 0.024383344 | K35: =(K26+K17)*Assumptions!$D$9*3/100 -> 0.031805927 | L35: =SUM(D35:K35) -> 0.098174651
A36: 26 | B36: Revenue | C36: Rs crore | D36: =SUM(D30:D35) -> 0.158464 | E36: =SUM(E30:E35) -> 0.49347608 | F36: =SUM(F30:F35) -> 1.0231661 | G36: =SUM(G30:G35) -> 1.5895673 | H36: =SUM(H30:H35) -> 2.192772 | I36: =SUM(I30:I35) -> 2.6449447 | J36: =SUM(J30:J35) -> 3.1218387 | K36: =SUM(K30:K35) -> 3.4238027 | L36: =SUM(D36:K36) -> 14.648032
A37: 27 | B37: Cost: AI | C37: Rs crore | D37: =D18*Assumptions!$D$47*3/100 -> 0.034545434 | E37: =E18*Assumptions!$D$47*3/100 -> 0.10757635 | F37: =F18*Assumptions!$D$47*3/100 -> 0.22304239 | G37: =G18*Assumptions!$D$47*3/100 -> 0.34650351 | H37: =H18*Assumptions!$D$47*3/100 -> 0.47797892 | I37: =I18*Assumptions!$D$47*3/100 -> 0.57651924 | J37: =J18*Assumptions!$D$47*3/100 -> 0.68044087 | K37: =K18*Assumptions!$D$47*3/100 -> 0.74621876 | L37: =SUM(D37:K37) -> 3.1928255
A38: 28 | B38: Cost: photo checks at handover | C38: Rs crore | D38: =D19*Assumptions!$D$48*90*Assumptions!$D$49/100 -> 0.0025909075 | E38: =E19*Assumptions!$D$48*90*Assumptions!$D$49/100 -> 0.008068226 | F38: =F19*Assumptions!$D$48*90*Assumptions!$D$49/100 -> 0.016728179 | G38: =G19*Assumptions!$D$48*90*Assumptions!$D$49/100 -> 0.025987763 | H38: =H19*Assumptions!$D$48*90*Assumptions!$D$49/100 -> 0.035848419 | I38: =I19*Assumptions!$D$48*90*Assumptions!$D$49/100 -> 0.043238943 | J38: =J19*Assumptions!$D$48*90*Assumptions!$D$49/100 -> 0.051033065 | K38: =K19*Assumptions!$D$48*90*Assumptions!$D$49/100 -> 0.055966407 | L38: =SUM(D38:K38) -> 0.23946191
A39: 29 | B39: Cost: Account Aggregator data | C39: Rs crore | D39: =D14*Assumptions!$D$50*3/100 -> 0.021537054 | E39: =E14*Assumptions!$D$50*3/100 -> 0.067013839 | F39: =F14*Assumptions!$D$50*3/100 -> 0.13883304 | G39: =G14*Assumptions!$D$50*3/100 -> 0.21545759 | H39: =H14*Assumptions!$D$50*3/100 -> 0.2968875 | I39: =I14*Assumptions!$D$50*3/100 -> 0.35758125 | J39: =J14*Assumptions!$D$50*3/100 -> 0.42147857 | K39: =K14*Assumptions!$D$50*3/100 -> 0.46143616 | L39: =SUM(D39:K39) -> 1.980225
A40: 30 | B40: Cost: support | C40: Rs crore | D40: =D18*Assumptions!$D$51*3/100 -> 0.017272717 | E40: =E18*Assumptions!$D$51*3/100 -> 0.053788173 | F40: =F18*Assumptions!$D$51*3/100 -> 0.1115212 | G40: =G18*Assumptions!$D$51*3/100 -> 0.17325175 | H40: =H18*Assumptions!$D$51*3/100 -> 0.23898946 | I40: =I18*Assumptions!$D$51*3/100 -> 0.28825962 | J40: =J18*Assumptions!$D$51*3/100 -> 0.34022043 | K40: =K18*Assumptions!$D$51*3/100 -> 0.37310938 | L40: =SUM(D40:K40) -> 1.5964127
A41: 31 | B41: Cost: onboarding new members | C41: Rs crore | D41: =D15*(Assumptions!$D$52+Assumptions!$D$53*1)/100 -> 0.12922232 | E41: =E15*(Assumptions!$D$52+Assumptions!$D$53*1)/100 -> 0.27286071 | F41: =F15*(Assumptions!$D$52+Assumptions!$D$53*1)/100 -> 0.43091518 | G41: =G15*(Assumptions!$D$52+Assumptions!$D$53*1)/100 -> 0.45974732 | H41: =H15*(Assumptions!$D$52+Assumptions!$D$53*1)/100 -> 0.48857946 | I41: =I15*(Assumptions!$D$52+Assumptions!$D$53*1)/100 -> 0.3641625 | J41: =J15*(Assumptions!$D$52+Assumptions!$D$53*1)/100 -> 0.38338393 | K41: =K15*(Assumptions!$D$52+Assumptions!$D$53*1)/100 -> 0.23974554 | L41: =SUM(D41:K41) -> 2.768617
A42: 32 | B42: Cost: collection and servicing of drawdowns | C42: Rs crore | D42: =D22*Assumptions!$D$39 -> 0.0064611161 | E42: =E22*Assumptions!$D$39 -> 0.020104152 | F42: =F22*Assumptions!$D$39 -> 0.041649911 | G42: =G22*Assumptions!$D$39 -> 0.064637277 | H42: =H22*Assumptions!$D$39 -> 0.08906625 | I42: =I22*Assumptions!$D$39 -> 0.10727438 | J42: =J22*Assumptions!$D$39 -> 0.12644357 | K42: =K22*Assumptions!$D$39 -> 0.13843085 | L42: =SUM(D42:K42) -> 0.5940675
...

Sheet Summary
B1: Summary: numbers for the projection and business-model slides
B2: All cells link to the Model, Assumptions and Baseline sheets.
B4: A. Base case, quarter by quarter
B5: Metric | C5: Unit | D5: Q4 FY27 | E5: Q1 FY28 | F5: Q2 FY28 | G5: Q3 FY28 | H5: Q4 FY28 | I5: Q1 FY29 | J5: Q2 FY29 | K5: Q3 FY29 | L5: 8-qtr total
B6: Baseline Paytm merchant GMV (FORECAST) | C6: Rs lakh crore | D6: =Model!D358 -> 7.9486905 | E6: =Model!E358 -> 8.2971429 | F6: =Model!F358 -> 8.6455952 | G6: =Model!G358 -> 8.9940476 | H6: =Model!H358 -> 9.3425 | I6: =Model!I358 -> 9.6909524 | J6: =Model!J358 -> 10.039405 | K6: =Model!K358 -> 10.387857 | L6: =Model!L358 -> 73.34619
B7: Paying members, all sizes | C7: lakh | D7: =Model!D346 -> 0.098633079 | E7: =Model!E346 -> 0.30690276 | F7: =Model!F346 -> 0.63581259 | G7: =Model!G346 -> 0.98672946 | H7: =Model!H346 -> 1.3596534 | I7: =Model!I346 -> 1.6376121 | J7: =Model!J346 -> 1.9302422 | K7: =Model!K346 -> 2.1132356 | L7: =Model!L346 -> 2.1132356
B8: of which single-outlet | C8: lakh | D8: =Model!D210 -> 0.06185 | E8: =Model!E210 -> 0.19245 | F8: =Model!F210 -> 0.3987 | G8: =Model!G210 -> 0.61875 | H8: =Model!H210 -> 0.8526 | I8: =Model!I210 -> 1.0269 | J8: =Model!J210 -> 1.2104 | K8: =Model!K210 -> 1.32515 | L8: =Model!L210 -> 1.32515
B9: of which 2-5 outlets | C9: lakh | D9: =Model!D244 -> 0.035342857 | E9: =Model!E244 -> 0.10997143 | F9: =Model!F244 -> 0.22782857 | G9: =Model!G244 -> 0.35357143 | H9: =Model!H244 -> 0.4872 | I9: =Model!I244 -> 0.5868 | J9: =Model!J244 -> 0.69165714 | K9: =Model!K244 -> 0.75722857 | L9: =Model!L244 -> 0.75722857
B10: of which 6-20 outlets | C10: lakh | D10: =Model!D279 -> 0.0014137143 | E10: =Model!E279 -> 0.0043988571 | F10: =Model!F279 -> 0.0091131429 | G10: =Model!G279 -> 0.014142857 | H10: =Model!H279 -> 0.019488 | I10: =Model!I279 -> 0.023472 | J10: =Model!J279 -> 0.027666286 | K10: =Model!K279 -> 0.030289143 | L10: =Model!L279 -> 0.030289143
B11: of which 21+ outlets | C11: lakh | D11: =Model!D316 -> 2.6507143e-05 | E11: =Model!E316 -> 8.2478571e-05 | F11: =Model!F316 -> 0.00017087143 | G11: =Model!G316 -> 0.00026517857 | H11: =Model!H316 -> 0.0003654 | I11: =Model!I316 -> 0.0004401 | J11: =Model!J316 -> 0.00051874286 | K11: =Model!K316 -> 0.00056792143 | L11: =Model!L316 -> 0.00056792143
B12: Member outlets | C12: lakh | D12: =Model!D348 -> 0.16748817 | E12: =Model!E348 -> 0.52164268 | F12: =Model!F348 -> 1.0816967 | G12: =Model!G348 -> 1.6807654 | H12: =Model!H348 -> 2.3189587 | I12: =Model!I348 -> 2.7977567 | J12: =Model!J348 -> 3.3028579 | K12: =Model!K348 -> 3.6232491 | L12: =Model!L348 -> 3.6232491
B13: Incremental GMV | C13: Rs crore | D13: =Model!D356 -> 20.125955 | E13: =Model!E356 -> 65.386165 | F13: =Model!F356 -> 141.10175 | G13: =Model!G356 -> 230.53594 | H13: =Model!H356 -> 334.32046 | I13: =Model!I356 -> 429.22003 | J13: =Model!J356 -> 534.96284 | K13: =Model!K356 -> 626.60787 | L13: =Model!L356 -> 2382.261
B14: of which extra sales from the cash plan | C14: Rs crore | D14: =Model!D351 -> 7.34778 | E14: =Model!E351 -> 22.86306 | F14: =Model!F351 -> 47.36556 | G14: =Model!G351 -> 73.5075 | H14: =Model!H351 -> 101.28888 | I14: =Model!I351 -> 121.99572 | J14: =Model!J351 -> 143.79552 | K14: =Model!K351 -> 157.42782 | L14: =Model!L351 -> 675.59184
B15: of which collections moved to Paytm's outlet QRs | C15: Rs crore | D15: =Model!D352 -> 8.516745 | E15: =Model!E352 -> 26.500365 | F15: =Model!F352 -> 54.90099 | G15: =Model!G352 -> 85.201875 | H15: =Model!H352 -> 117.40302 | I15: =Model!I352 -> 141.40413 | J15: =Model!J352 -> 166.67208 | K15: =Model!K352 -> 182.47315 | L15: =Model!L352 -> 783.07236
B16: of which leakage recovered | C16: Rs crore | D16: =Model!D353 -> 1.5058553 | E16: =Model!E353 -> 4.6884599 | F16: =Model!F353 -> 9.7190313 | G16: =Model!G353 -> 15.095261 | H16: =Model!H353 -> 20.817798 | I16: =Model!I353 -> 25.101442 | J16: =Model!J353 -> 29.617252 | K16: =Model!K353 -> 32.467817 | L16: =Model!L353 -> 139.01292
B17: of which kept by lower device churn | C17: Rs crore | D17: =Model!D354 -> 1.8415153 | E17: =Model!E354 -> 7.5760713 | F17: =Model!F354 -> 19.465714 | G17: =Model!G354 -> 37.936562 | H17: =Model!H354 -> 63.415757 | I17: =Model!I354 -> 94.147543 | J17: =Model!J354 -> 130.41872 | K17: =Model!K354 -> 170.19589 | L17: =Model!L354 -> 524.99777
B18: of which extra outlets opened | C18: Rs crore | D18: =Model!D355 -> 0.91405906 | E18: =Model!E355 -> 3.7582089 | F18: =Model!F355 -> 9.6504538 | G18: =Model!G355 -> 18.794739 | H18: =Model!H355 -> 31.39501 | I18: =Model!I355 -> 46.571198 | J18: =Model!J355 -> 64.459268 | K18: =Model!K355 -> 84.043186 | L18: =Model!L355 -> 259.58612
B19: Uplift vs baseline GMV | C19: % | D19: =Model!D359 -> 2.5319837e-05 | E19: =Model!E359 -> 7.880564e-05 | F19: =Model!F359 -> 0.00016320652 | G19: =Model!G359 -> 0.00025632057 | H19: =Model!H359 -> 0.00035784904 | I19: =Model!I359 -> 0.000442908 | J19: =Model!J359 -> 0.0005328631 | K19: =Model!K359 -> 0.00060321187 | L19: =Model!L359 -> 0.00032479683
B20: Drawdowns prompted by members' cash plans | C20: Rs crore | D20: =Model!D350 -> 29.581971 | E20: =Model!E350 -> 92.046086 | F20: =Model!F350 -> 190.69251 | G20: =Model!G350 -> 295.93929 | H20: =Model!H350 -> 407.7864 | I20: =Model!I350 -> 491.1516 | J20: =Model!J350 -> 578.91703 | K20: =Model!K350 -> 633.80031 | L20: =Model!L350 -> 2719.9152
B21: Revenue | C21: Rs crore | D21: =Model!D367 -> 1.4430967 | E21: =Model!E367 -> 4.4953516 | F21: =Model!F367 -> 9.3234006 | G21: =Model!G367 -> 14.490365 | H21: =Model!H367 -> 19.997406 | I21: =Model!I367 -> 24.134265 | J21: =Model!J367 -> 28.500185 | K21: =Model!K367 -> 31.277196 | L21: =Model!L367 -> 133.66127
B22: of which membership | C22: Rs crore | D22: =Model!D360 -> 0.58883948 | E22: =Model!E360 -> 1.8322095 | F22: =Model!F360 -> 3.7958011 | G22: =Model!G360 -> 5.8907749 | H22: =Model!H360 -> 8.1171308 | I22: =Model!I360 -> 9.7765442 | J22: =Model!J360 -> 11.523546 | K22: =Model!K360 -> 12.616017 | L22: =Model!L360 -> 54.140863
B23: of which outlet add-ons | C23: Rs crore | D23: =Model!D361 -> 0.017511944 | E23: =Model!E361 -> 0.054489468 | F23: =Model!F361 -> 0.11288621 | G23: =Model!G361 -> 0.17519022 | H23: =Model!H361 -> 0.24140151 | I23: =Model!I361 -> 0.29075207 | J23: =Model!J361 -> 0.34270747 | K23: =Model!K361 -> 0.37519729 | L23: =Model!L361 -> 1.6101362
B24: of which shift-check passes | C24: Rs crore | D24: =Model!D362 -> 0.17487474 | E24: =Model!E362 -> 0.54449824 | F24: =Model!F362 -> 1.1287852 | G24: =Model!G362 -> 1.7533074 | H24: =Model!H362 -> 2.4181462 | I24: =Model!I362 -> 2.9159931 | J24: =Model!J362 -> 3.4408806 | K24: =Model!K362 -> 3.7724671 | L24: =Model!L362 -> 16.148953
B25: of which CA packs | C25: Rs crore | D25: =Model!D363 -> 0.058588049 | E25: =Model!E363 -> 0.18230024 | F25: =Model!F363 -> 0.37767268 | G25: =Model!G363 -> 0.5861173 | H25: =Model!H363 -> 0.80763412 | I25: =Model!I363 -> 0.97274159 | J25: =Model!J363 -> 1.1465638 | K25: =Model!K363 -> 1.255262 | L25: =Model!L363 -> 5.3868798
B26: of which credit (paid by lenders) | C26: Rs crore | D26: =Model!D364 -> 0.59163943 | E26: =Model!E364 -> 1.8409217 | F26: =Model!F364 -> 3.8138503 | G26: =Model!G364 -> 5.9187857 | H26: =Model!H364 -> 8.155728 | I26: =Model!I364 -> 9.823032 | J26: =Model!J364 -> 11.578341 | K26: =Model!K364 -> 12.676006 | L26: =Model!L364 -> 54.398304
B27: of which payment margin and device subscriptions | C27: Rs crore | D27: =Model!D365+Model!D366 -> 0.011643019 | E27: =Model!E365+Model!E366 -> 0.040932466 | F27: =Model!F365+Model!F366 -> 0.094405076 | G27: =Model!G365+Model!G366 -> 0.16618993 | H27: =Model!H365+Model!H366 -> 0.25736501 | I27: =Model!I365+Model!I366 -> 0.35520231 | J27: =Model!J365+Model!J366 -> 0.46814629 | K27: =Model!K365+Model!K366 -> 0.58224684 | L27: =Model!L365+Model!L366 -> 1.9761309
B28: Variable cost | C28: Rs crore | D28: =Model!D375 -> 0.89595755 | E28: =Model!E375 -> 2.3935098 | F28: =Model!F375 -> 4.5493002 | G28: =Model!G375 -> 6.4241371 | H28: =Model!H375 -> 8.4131684 | I28: =Model!I375 -> 9.4539998 | J28: =Model!J375 -> 11.010326 | K28: =Model!K375 -> 11.514005 | L28: =Model!L375 -> 54.654405
B29: Contribution to Paytm | C29: Rs crore | D29: =Model!D376 -> 0.5471391 | E29: =Model!E376 -> 2.1018418 | F29: =Model!F376 -> 4.7741005 | G29: =Model!G376 -> 8.0662284 | H29: =Model!H376 -> 11.584237 | I29: =Model!I376 -> 14.680266 | J29: =Model!J376 -> 17.489858 | K29: =Model!K376 -> 19.763191 | L29: =Model!L376 -> 79.006862
B30: of which single-outlet members | C30: Rs crore | D30: =Model!D241 -> 0.28897673 | E30: =Model!E241 -> 1.0802628 | F30: =Model!F241 -> 2.4280338 | G30: =Model!G241 -> 4.0654486 | H30: =Model!H241 -> 5.8135449 | I30: =Model!I241 -> 7.3300191 | J30: =Model!J241 -> 8.7217251 | K30: =Model!K241 -> 9.8241099 | L30: =Model!L241 -> 39.552121
B31: of which 2-5 outlet members | C31: Rs crore | D31: =Model!D276 -> 0.23911021 | E31: =Model!E276 -> 0.92303651 | F31: =Model!F276 -> 2.1007465 | G31: =Model!G276 -> 3.5556847 | H31: =Model!H276 -> 5.1116646 | I31: =Model!I276 -> 6.4856462 | J31: =Model!J276 -> 7.7316257 | K31: =Model!K276 -> 8.7450335 | L31: =Model!L276 -> 34.892548
B32: of which 6-20 outlet members | C32: Rs crore | D32: =Model!D313 -> 0.029002626 | E32: =Model!E313 -> 0.11244904 | F32: =Model!F313 -> 0.25634523 | G32: =Model!G313 -> 0.43449186 | H32: =Model!H313 -> 0.62504218 | I32: =Model!I313 -> 0.79366687 | J32: =Model!J313 -> 0.94633559 | K32: =Model!K313 -> 1.0708972 | L32: =Model!L313 -> 4.2682306
B33: of which 21+ outlet members | C33: Rs crore | D33: =Model!D344 -> -0.0099504581 | E33: =Model!E344 -> -0.013906534 | F33: =Model!F344 -> -0.011025068 | G33: =Model!G344 -> 0.010603282 | H33: =Model!H344 -> 0.033985476 | I33: =Model!I344 -> 0.070933395 | J33: =Model!J344 -> 0.0901718 | K33: =Model!K344 -> 0.1231502 | L33: =Model!L344 -> 0.29396209
B34: Contribution margin | C34: % | D34: =Model!D377 -> 0.37914238 | E34: =Model!E377 -> 0.46755893 | F34: =Model!F377 -> 0.5120557 | G34: =Model!G377 -> 0.55666149 | H34: =Model!H377 -> 0.579287 | I34: =Model!I377 -> 0.60827481 | J34: =Model!J377 -> 0.61367526 | K34: =Model!K377 -> 0.6318722 | L34: =Model!L377 -> 0.59109766
B35: Quarterly contribution vs Q1 FY27 EBITDA (Rs 203 crore) | C35: % | D35: =Model!D385 -> 0.0026952665 | E35: =Model!E385 -> 0.010353901 | F35: =Model!F385 -> 0.023517736 | G35: =Model!G385 -> 0.039735115 | H35: =Model!H385 -> 0.057065208 | I35: =Model!I385 -> 0.072316579 | J35: =Model!J385 -> 0.086156937 | K35: =Model!K385 -> 0.09735562
B37: B. Scenarios side by side
B38: Metric | C38: Unit | D38: Bear | E38: Base | F38: Bull
B39: Incremental GMV, 8 quarters | C39: Rs crore | D39: =Model!L160 -> 186.25748 | E39: =Model!L356 -> 2382.261 | F39: =Model!L552 -> 14354.037
B40: Incremental GMV in Q3 FY29 | C40: Rs crore | D40: =Model!K160 -> 50.545575 | E40: =Model!K356 -> 626.60787 | F40: =Model!K552 -> 3747.4101
B41: Uplift vs baseline GMV at Q3 FY29 | C41: % | D41: =Model!K163 -> 4.8658327e-05 | E41: =Model!K359 -> 0.00060321187 | F41: =Model!K555 -> 0.003607491
B42: Contribution to Paytm, 8 quarters | C42: Rs crore | D42: =Model!L180 -> 2.0934593 | E42: =Model!L376 -> 79.006862 | F42: =Model!L572 -> 707.01042
...

Sheet Sources
A1: Sources
A3: ID | B3: What it supports | C3: Link
A4: S1 | B4: Paytm Q1 FY27 earnings release (agent datapack): GMV, subscription merchants, net payment revenue 8.4 bps, processing margin >4 bps, cashback | C4: https://paytm.com/document/ir/financial-results/fy2026-27/Paytm_Q1_FY27_Agent_Datapack.md
A5: S2 | B5: Q2 FY26 (Sep-25): GMV Rs 5.67 lakh crore, subscriptions 1.37 crore | C5: https://ianslive.in/paytms-profitability-improves-to-rs-211-crore-in-q2-revenue-up-24-pc--20251104222037
A6: S3 | B6: Q3 FY26 (Dec-25): GMV Rs 6.2 lakh crore | C6: https://www.businesstoday.in/amp/latest/corporate/story/paytms-q3-net-profit-jumps-to-rs225-crore-on-upi-surge-and-merchant-services-boost-513573-2026-01-29
A7: S4 | B7: Q4 FY25 (Mar-25): GMV Rs 5.1 lakh crore, subscriptions 1.24 crore | C7: https://www.business-standard.com/companies/quarterly-results/one-97-communication-paytm-q4-fy25-result-loss-profit-revenue-stock-option-125050601030_1.html
A8: S5 | B8: Q3 FY25 (Dec-24): GMV Rs 5.0 lakh crore, up 13% QoQ from Rs 4.5 lakh crore; subscriptions 1.17 crore | C8: https://inc42.com/?p=495669
A9: S6 | B9: Q3 FY26 (Dec-25): subscription merchants 1.44 crore | C9: https://alphastreet.com/india/symbol/PAYTM
A10: S7 | B10: Soundbox rental Rs 125-150 a month (BofA merchant checks in Mumbai) | C10: https://www.outlookbusiness.com/amp/story/enterprise/bofa-research-paytm-soundbox-first-to-bring-audio-based-payments-confirmations-dominates-the-market-6795
A11: S8 | B11: Paytm subscription revenue ~Rs 90 per device a month (Q4 FY24) | C11: https://www.medianama.com/2024/10/223-paytm-to-monetize-soundbox-ads-in-partnership-with-meesho-a-shift-away-from-core-payments-business/
A12: S9 | B12: Several soundboxes on one counter (Inc42) | C12: https://inc42.com/buzz/upi-transactions-jump-3-8-mom-in-may-cross-23-bn-mark/
A13: S10 | B13: Paytm Q1 FY27 results: revenue Rs 2,448 crore, contribution profit Rs 1,350 crore at 55%, EBITDA Rs 203 crore, PAT Rs 220 crore, financial services Rs 814 crore | C13: https://paytm.com/blog/investor-relations/paytm-q1-fy27-results-revenue-grows-28-to-2448-crore-highest-ever-quarterly-ebitda-at-203-crore/
A14: S11 | B14: Paytm merchant loans, repeat borrowers (Aug 2022 release) | C14: https://bseindia.com/xml-data/corpfiling/AttachHis/01144943-65d3-465d-a4cc-f0556ff55ec5.pdf
... A42: S39 | B42: Merchant forum thread on Paytm Soundbox monthly charges rising from Rs 29 to Rs 135 (DesiDime; anecdotal) | C42: https://www.desidime.com/discussions/arbitrary-monthly-charges-on-paytm-business-soundbox
