Workbook

Sheet README
B2: Restock Agent (with Intent Guard) + Soundbox Care: 8-quarter GMV and contribution projection
B3: Paytm Build for India AI Hackathon, Mumbai | Track 1: Merchant Growth AI | Kamalika Poddar
B5: What this model does
B6: 1. Baseline: Paytm merchant GMV and device (subscription) merchants, projected with FORECAST (linear) on 8 reported quarters, Q2 FY25 to Q1 FY27. GROWTH (exponential) is shown alongside as a cross-check.
B7: 2. Restock Agent: grocery and FMCG shops order stock from their suppliers through an agent that pays inside the owner's limits (Intent Guard). Credit is routed to whichever rail gives the merchant the best hit rate: Paytm partner lenders, MUDRA credit line on UPI, OCEN or ONDC Financial Services, all underwritten with Account Aggregator data.
B8: 3. Soundbox Care: devices detect and fix their own faults, keep confirmations going on the owner's phone while down, and flag failures early, cutting field visits, replacements, downtime and churn.
B9: 4. Nearby (Phase 2): consented hyperlocal offers inside the Paytm app, priced per verified new customer. Off by default; switch on only if NPCI's 30% UPI cap is enforced.
B10: 5. Outputs: incremental GMV and contribution for 8 quarters from Q4 FY27 (Jan-Mar 2027 pilot) to Q3 FY29, in three scenarios (Bear, Base, Bull).
B12: How to use it
B13: Change blue cells on Assumptions (and reported actuals on Baseline). Every other number is a formula and recalculates.
B14: Colour code: blue text = input | black text = formula | green text = link to another sheet | yellow fill = key assumption.
B15: Units: lakh = 1,00,000 | crore = 1,00,00,000 | Rs 1 lakh crore = Rs 1,00,000 crore. Quarters follow India's April-March fiscal year.
... B29: Caveat: reported figures come from Paytm's disclosures, regulators and press coverage (see Sources). Everything else on Assumptions is a team estimate for a hackathon pitch, not Paytm data. Paytm's own device-ticket, lending and category data would replace several estimates directly.

Sheet Assumptions
A1: Assumptions: Restock Agent (with Intent Guard) + Soundbox Care
A2: Blue cells are inputs. Bear / Base / Bull columns feed the three scenario blocks on the Model sheet. Team estimates unless a source is named (Sources sheet).
A4: ID | B4: Assumption | C4: Unit | D4: Bear | E4: Base | F4: Bull | L4: Why this number / source
A5: Common
A6: K1 | B6: Payment processing margin on incremental GMV | C6: % of GMV | D6: 0.0004 | E6: 0.0004 | F6: 0.0004 | L6: Paytm Q1 FY27: payment processing margin 'comfortably above 4 bps' (S1, S10). Held at 4 bps in all scenarios.
A7: K2 | B7: Paytm-processed GMV per average device merchant per month | C7: Rs / month | D7: 50000 | E7: 60000 | F7: 80000 | L7: Team estimate. Ceiling check on Baseline: Q1 FY27 GMV / device merchants / 3 = ~Rs 1.5 lakh a month if all GMV came from device merchants (it does not).
A8: K3 | B8: Device subscription revenue per merchant per month | C8: Rs / month | D8: 80 | E8: 90 | F8: 100 | L8: ~Rs 90 per device a month in Q4 FY24 (S8); the Q1 FY27 release notes a modest YoY decline per device (S1).
A9: Restock Agent: scope and payment routing
A10: R1 | B10: Grocery and FMCG general-trade shops (kiranas, provision and general stores) among device merchants | C10: % of device merchants | D10: 0.3 | E10: 0.4 | F10: 0.5 | L10: Team estimate. Paytm does not disclose its merchant category mix.
A11: R2 | B11: Active users: covered eligible merchants who finish onboarding (supplier invoices captured or supplier linked) and order through the agent every month | C11: % of covered merchants | D11: 0.05 | E11: 0.1 | F11: 0.15 | L11: Team estimate. Onboarding is the data gate: no invoices or supplier link, no suggestions.
A12: R3 | B12: Supplier purchases per active merchant per month | C12: Rs / month | D12: 150000 | E12: 250000 | F12: 350000 | L12: Team estimate. Kirana gross margins on national brands run ~5-10% (S14), so purchases are ~90% of sales; the base implies ~Rs 2.75 lakh of monthly sales.
A13: R4 | B13: Share of purchases ordered through the agent | C13: % of purchases | D13: 0.2 | E13: 0.35 | F13: 0.5 | L13: Team estimate. FMCG companies' own retailer apps keep their share: HUL's Shikhar handled about a quarter of HUL's general trade by 2023 (S15).
A14: R5 | B14: Share of agent orders paid through Paytm (UPI, payment link or credit) | C14: % of agent orders | D14: 0.5 | E14: 0.7 | F14: 0.85 | L14: Team estimate. The rest stays cash or bank transfer; distributors opposing MDR may push cash (S16).
A15: R6 | B15: Share of those Paytm payments that are new to Paytm (previously cash, cheque, bank transfer or another app) | C15: % of Paytm-paid orders | D15: 0.4 | E15: 0.6 | F15: 0.75 | L15: Team estimate. Only new-to-Paytm payments count as incremental GMV.
A16: Restock Agent: credit, routed to the rail with the best hit rate (AA-based underwriting on every rail)
A17: R7 | B17: Share of agent-ordered value where the merchant asks for pay-later | C17: % of agent orders | D17: 0.15 | E17: 0.25 | F17: 0.35 | L17: Team estimate. Distributors already give 7-21 days of free credit, so pay-later has to beat it.
A18: R8 | B18: Router hit rate: share of pay-later requests approved on at least one rail | C18: % of requests | D18: 0.35 | E18: 0.5 | F18: 0.65 | L18: Benchmarks: public-sector banks' digital MSME model approved ~47% of applications in Apr-Oct FY26 (S12); open-network leads approve under 1% (team field estimate); a MUDRA credit line on UPI clears instantly when it has headroom (S18).
A19: R9 | B19: Rail mix: Paytm partner lenders (pay-later paid straight to the supplier) | C19: % of pay-later value | D19: 0.45 | E19: 0.45 | F19: 0.45 | L19: Team estimate of where merchant-first routing lands. Same in all scenarios.
A20: R10 | B20: Rail mix: MUDRA credit line on UPI | C20: % of pay-later value | D20: 0.25 | E20: 0.25 | F20: 0.25 | L20: Credit line on UPI covers PM MUDRA loans, with 8 banks live since Sep 2026 (S18).
A21: R11 | B21: Rail mix: OCEN lenders | C21: % of pay-later value | D21: 0.15 | E21: 0.15 | F21: 0.15 | L21: Team estimate. OCEN handled 5,641 loans in Q1 2025 (Mohalla model sources).
A22: R12 | B22: Rail mix: ONDC Financial Services lenders | C22: % of pay-later value | D22: =1-D19-D20-D21 -> 0.15 | E22: =1-E19-E20-E21 -> 0.15 | F22: =1-F19-F20-F21 -> 0.15 | L22: Formula: the remainder.
A23: R13 | B23: Paytm take per 30-day pay-later cycle: partner lenders | C23: % of value per cycle | D23: 0.003 | E23: 0.005 | F23: 0.007 | L23: Team estimate: a share of the lender's ~1.5-2% monthly yield (18-24% a year). Paytm doesn't publish take rates.
A24: R14 | B24: Paytm take per cycle: MUDRA credit line on UPI | C24: % of value per cycle | D24: 0 | E24: 0 | F24: 0.001 | L24: Pays Paytm little or nothing directly; any interchange on credit-line UPI payments is unconfirmed.
A25: R15 | B25: Paytm take per cycle: OCEN (Paytm as loan service provider) | C25: % of value per cycle | D25: 0.002 | E25: 0.004 | F25: 0.005 | L25: Team estimate.
A26: R16 | B26: Paytm take per cycle: ONDC Financial Services (Paytm as buyer app) | C26: % of value per cycle | D26: 0.002 | E26: 0.003 | F26: 0.005 | L26: Team estimate.
A27: R17 | B27: Working-capital loans: share of active merchants taking a new loan through the router each year | C27: % per year | D27: 0.05 | E27: 0.1 | F27: 0.15 | L27: Team estimate, incremental to Paytm's existing lending: purchase history and verified suppliers improve approvals. Paytm merchant loans run 6-24 months with daily instalments (S11).
A28: R18 | B28: Average working-capital loan | C28: Rs per loan | D28: 100000 | E28: 150000 | F28: 200000 | L28: Team estimate. Paytm merchant loans go up to Rs 10 lakh (S11); MUDRA has averaged ~Rs 69,000 per loan over 11 years (S22).
A29: R19 | B29: Paytm revenue per working-capital loan (distribution and collection) | C29: % of loan value | D29: 0.02 | E29: 0.03 | F29: 0.04 | L29: Team estimate. Paytm doesn't publish take rates.
A30: R20 | B30: Paytm credit-loss sharing on partner-lender pay-later | C30: % of value per cycle | D30: 0.0025 | E30: 0.001 | F30: 0 | L30: Team estimate. RBI caps default-loss guarantees at 5% of a loan portfolio (S26); whether Paytm gives one to merchant-loan partners isn't public.
A31: R21 | B31: Paytm credit-loss sharing on working-capital loans | C31: % of loan value | D31: 0.015 | E31: 0.005 | F31: 0 | L31: Team estimate, as R20.
A32: Restock Agent: MDR, paid plan, merchant sales
A33: R22 | B33: MDR switch: 1 = MDR on UPI merchant payments above Rs 2,000 is live | C33: 1 or 0 | D33: 0 | E33: 1 | F33: 1 | L33: Finance Ministry notified MDR on 14 Sep 2026 (S17); NPCI deferred the 15 Oct start to after Diwali (S16). Bear assumes it doesn't reach distributors.
A34: R23 | B34: Share of new-to-Paytm supplier payments above Rs 2,000 that go to non-exempt (larger) distributors | C34: % of value | D34: 0.4 | E34: 0.6 | F34: 0.75 | L34: Team estimate. Restock invoices are usually above Rs 2,000; an exemption for businesses under Rs 40 lakh turnover was under consideration (S16).
A35: R24 | B35: Paytm's effective share of MDR, as % of payment value | C35: % of value | D35: 0.0005 | E35: 0.001 | F35: 0.0015 | L35: MDR is ~0.40%, capped at Rs 300 (S16), split among banks, payment aggregators and apps; the split isn't decided (S17). Paytm earns most where it acquires the distributor.
A36: R25 | B36: Paid plan attach rate (autopilot ordering, Intent Guard, credit routing) | C36: % of active merchants | D36: 0.1 | E36: 0.2 | F36: 0.3 | L36: Team estimate.
A37: R26 | B37: Paid plan price | C37: Rs / month | D37: 49 | E37: 99 | F37: 149 | L37: Anchored to Soundbox rental of Rs 125-150 a month (S7).
A38: R27 | B38: Paytm-processed sales per active Restock merchant per month, before Restock | C38: Rs / month | D38: 50000 | E38: 80000 | F38: 120000 | L38: Team estimate, same as the Mohalla model's A8.
A39: R28 | B39: Sales increase from fewer stock-outs and more stock on credit | C39: % of sales | D39: 0.01 | E39: 0.02 | F39: 0.03 | L39: Team estimate. No public figure for kirana stock-out losses; HUL built Shikhar partly to tackle stock-outs (S15). The pilot measures this against holdout shops.
A40: Restock Agent: costs
A41: R29 | B41: AI cost per active merchant (invoice reading, voice, agent) | C41: Rs / month | D41: 25 | E41: 15 | F41: 10 | L41: Team estimate.
...

Sheet Baseline
A1: Baseline: Paytm merchant GMV and device merchants
A2: Rows 5-12 are reported actuals (blue). Rows 13-22 are FORECAST (linear) on those 8 quarters. Column G is GROWTH (exponential) as a cross-check. The model uses the linear forecast.
A4: x (period) | B4: Quarter | C4: Months | D4: Type | E4: Merchant GMV (Rs lakh crore) | F4: GMV YoY | G4: Cross-check: GROWTH (Rs lakh crore) | H4: Device merchants (crore) | I4: Source / method
A5: 1 | B5: Q2 FY25 | C5: Jul-Sep 2024 | D5: Actual | E5: 4.5 | H5: 1.12 | I5: GMV: S5 (Q3 FY25 GMV up 13% QoQ from Rs 4.5 lakh crore). Device merchants: derived, 1.17 crore at Dec-24 minus 5 lakh added that quarter (S5).
A6: 2 | B6: Q3 FY25 | C6: Oct-Dec 2024 | D6: Actual | E6: 5 | H6: 1.17 | I6: S5
A7: 3 | B7: Q4 FY25 | C7: Jan-Mar 2025 | D7: Actual | E7: 5.1 | H7: 1.24 | I7: S4
A8: 4 | B8: Q1 FY26 | C8: Apr-Jun 2025 | D8: Actual | E8: 5.4 | H8: 1.3 | I8: S1 (Jun-25 column of the Q1 FY27 release)
A9: 5 | B9: Q2 FY26 | C9: Jul-Sep 2025 | D9: Actual | E9: 5.67 | F9: =E9/E5-1 -> 0.26 | H9: 1.37 | I9: S2
A10: 6 | B10: Q3 FY26 | C10: Oct-Dec 2025 | D10: Actual | E10: 6.2 | F10: =E10/E6-1 -> 0.24 | H10: 1.44 | I10: GMV: S3. Device merchants: S6
A11: 7 | B11: Q4 FY26 | C11: Jan-Mar 2026 | D11: Actual | E11: 6.5 | F11: =E11/E7-1 -> 0.2745098 | H11: 1.51 | I11: S1 (Mar-26 column)
A12: 8 | B12: Q1 FY27 | C12: Apr-Jun 2026 | D12: Actual | E12: 7.1 | F12: =E12/E8-1 -> 0.31481481 | H12: 1.57 | I12: S1, S10
A13: 9 | B13: Q2 FY27 | C13: Jul-Sep 2026 | D13: Forecast | E13: =FORECAST(A13,$E$5:$E$12,$A$5:$A$12) -> 7.2517857 | F13: =E13/E9-1 -> 0.27897455 | G13: =GROWTH($E$5:$E$12,$A$5:$A$12,A13) -> 7.4103976 | H13: =FORECAST(A13,$H$5:$H$12,$A$5:$A$12) -> 1.6357143 | I13: FORECAST (linear) on rows 5-12. Not yet reported; bridges to the projection window.
A14: 10 | B14: Q3 FY27 | C14: Oct-Dec 2026 | D14: Forecast | E14: =FORECAST(A14,$E$5:$E$12,$A$5:$A$12) -> 7.6002381 | F14: =E14/E10-1 -> 0.22584485 | G14: =GROWTH($E$5:$E$12,$A$5:$A$12,A14) -> 7.8778783 | H14: =FORECAST(A14,$H$5:$H$12,$A$5:$A$12) -> 1.7014286 | I14: FORECAST (linear) on rows 5-12. Not yet reported; bridges to the projection window. Rows 15-22 (shaded) are the 8-quarter projection window.
A15: 11 | B15: Q4 FY27 | C15: Jan-Mar 2027 | D15: Forecast | E15: =FORECAST(A15,$E$5:$E$12,$A$5:$A$12) -> 7.9486905 | F15: =E15/E11-1 -> 0.22287546 | G15: =GROWTH($E$5:$E$12,$A$5:$A$12,A15) -> 8.3748497 | H15: =FORECAST(A15,$H$5:$H$12,$A$5:$A$12) -> 1.7671429 | I15: FORECAST (linear) on rows 5-12
A16: 12 | B16: Q1 FY28 | C16: Apr-Jun 2027 | D16: Forecast | E16: =FORECAST(A16,$E$5:$E$12,$A$5:$A$12) -> 8.2971429 | F16: =E16/E12-1 -> 0.16861167 | G16: =GROWTH($E$5:$E$12,$A$5:$A$12,A16) -> 8.9031723 | H16: =FORECAST(A16,$H$5:$H$12,$A$5:$A$12) -> 1.8328571 | I16: FORECAST (linear) on rows 5-12
A17: 13 | B17: Q2 FY28 | C17: Jul-Sep 2027 | D17: Forecast | E17: =FORECAST(A17,$E$5:$E$12,$A$5:$A$12) -> 8.6455952 | F17: =E17/E13-1 -> 0.19220225 | G17: =GROWTH($E$5:$E$12,$A$5:$A$12,A17) -> 9.4648238 | H17: =FORECAST(A17,$H$5:$H$12,$A$5:$A$12) -> 1.8985714 | I17: FORECAST (linear) on rows 5-12
A18: 14 | B18: Q3 FY28 | C18: Oct-Dec 2027 | D18: Forecast | E18: =FORECAST(A18,$E$5:$E$12,$A$5:$A$12) -> 8.9940476 | F18: =E18/E14-1 -> 0.18339024 | G18: =GROWTH($E$5:$E$12,$A$5:$A$12,A18) -> 10.061907 | H18: =FORECAST(A18,$H$5:$H$12,$A$5:$A$12) -> 1.9642857 | I18: FORECAST (linear) on rows 5-12
A19: 15 | B19: Q4 FY28 | C19: Jan-Mar 2028 | D19: Forecast | E19: =FORECAST(A19,$E$5:$E$12,$A$5:$A$12) -> 9.3425 | F19: =E19/E15-1 -> 0.17535084 | G19: =GROWTH($E$5:$E$12,$A$5:$A$12,A19) -> 10.696656 | H19: =FORECAST(A19,$H$5:$H$12,$A$5:$A$12) -> 2.03 | I19: FORECAST (linear) on rows 5-12
A20: 16 | B20: Q1 FY29 | C20: Apr-Jun 2028 | D20: Forecast | E20: =FORECAST(A20,$E$5:$E$12,$A$5:$A$12) -> 9.6909524 | F20: =E20/E16-1 -> 0.16798669 | G20: =GROWTH($E$5:$E$12,$A$5:$A$12,A20) -> 11.371449 | H20: =FORECAST(A20,$H$5:$H$12,$A$5:$A$12) -> 2.0957143 | I20: FORECAST (linear) on rows 5-12
A21: 17 | B21: Q2 FY29 | C21: Jul-Sep 2028 | D21: Forecast | E21: =FORECAST(A21,$E$5:$E$12,$A$5:$A$12) -> 10.039405 | F21: =E21/E17-1 -> 0.16121614 | G21: =GROWTH($E$5:$E$12,$A$5:$A$12,A21) -> 12.08881 | H21: =FORECAST(A21,$H$5:$H$12,$A$5:$A$12) -> 2.1614286 | I21: FORECAST (linear) on rows 5-12
A22: 18 | B22: Q3 FY29 | C22: Oct-Dec 2028 | D22: Forecast | E22: =FORECAST(A22,$E$5:$E$12,$A$5:$A$12) -> 10.387857 | F22: =E22/E18-1 -> 0.15497022 | G22: =GROWTH($E$5:$E$12,$A$5:$A$12,A22) -> 12.851426 | H22: =FORECAST(A22,$H$5:$H$12,$A$5:$A$12) -> 2.2271429 | I22: FORECAST (linear) on rows 5-12
A25: Reported reference points (Q1 FY27, quarter ended 30 June 2026) and checks
B26: Revenue from operations | D26: Rs crore | F26: 2448 | I26: S10 (up 28% YoY)
B27: Contribution profit | D27: Rs crore | F27: 1350 | I27: S10 (up 17% YoY)
B28: Contribution margin | D28: % of revenue | F28: 0.55 | I28: S10
B29: EBITDA | D29: Rs crore | F29: 203 | I29: S10 (8% margin, highest ever)
B30: Profit after tax | D30: Rs crore | F30: 220 | I30: S10 (up 79% YoY)
B31: Financial services revenue (merchant loans, personal loans, insurance distribution) | D31: Rs crore | F31: 814 | I31: S10 (up 45% YoY)
B32: Net payment revenue, excluding PIDF | D32: Rs crore | F32: 601 | I32: S1, S10
B33: Net payment revenue per Rs of GMV | D33: bps | F33: =F32/(E12*100000)*10000 -> 8.4647887 | I33: Formula. Paytm reports 8.4 bps (S1).
B34: Payment processing margin (reported as 'comfortably above 4 bps') | D34: bps | F34: 4 | I34: S1, S10
B35: Net payment revenue from a 1% GMV lift, at the blended rate | D35: Rs crore per quarter | F35: =E12*100000*0.01*F33/10000 -> 6.01 | I35: Formula. Blended rate; payments under Rs 2,000 carry no MDR, so kirana UPI earns far less.
B36: Marketing Services revenue | D36: Rs crore | F36: 239 | I36: S1 (down 3% YoY)
B37: Promotional cashback and incentives | D37: Rs crore | F37: 90 | I37: S1 (up 143% YoY)
B38: Registered merchants | D38: crore | F38: 5 | I38: S1
B39: Ceiling: GMV per device merchant per month if all GMV came from device merchants | D39: Rs / month | F39: =E12*1000000000000/(H12*10000000)/3 -> 150743.1 | I39: Formula. Upper bound used to sanity-check K2 and R27.
B40: Q3 FY29 baseline: GROWTH cross-check vs FORECAST | D40: % above linear | F40: =G22/E22-1 -> 0.2371585 | I40: Formula. How conservative the linear baseline is.
B41: Mohalla Network (assessed and dropped): base-case contribution over the same 8 quarters | D41: Rs crore | F41: 29.52 | I41: Mohalla_GMV_Projection.xlsx, Summary sheet, base case. Kept for comparison.

Sheet Model
A1: Model: Restock Agent (with Intent Guard) + Soundbox Care, quarter by quarter
A2: Every cell is a formula. Assumption references: Bear = Assumptions column D, Base = E, Bull = F. Column L sums flows over the 8 quarters; stock rows show Q3 FY29; ratio rows divide the 8-quarter totals.
A4: # | B4: Quarter | C4: Unit | D4: Q4 FY27 | E4: Q1 FY28 | F4: Q2 FY28 | G4: Q3 FY28 | H4: Q4 FY28 | I4: Q1 FY29 | J4: Q2 FY29 | K4: Q3 FY29 | L4: 8-qtr total
B5: Months | D5: Jan-Mar 2027 | E5: Apr-Jun 2027 | F5: Jul-Sep 2027 | G5: Oct-Dec 2027 | H5: Jan-Mar 2028 | I5: Apr-Jun 2028 | J5: Jul-Sep 2028 | K5: Oct-Dec 2028
B6: Baseline period index (x) | D6: =Baseline!A15 -> 11 | E6: =Baseline!A16 -> 12 | F6: =Baseline!A17 -> 13 | G6: =Baseline!A18 -> 14 | H6: =Baseline!A19 -> 15 | I6: =Baseline!A20 -> 16 | J6: =Baseline!A21 -> 17 | K6: =Baseline!A22 -> 18
A8: BEAR scenario (Assumptions column D)
B9: Restock Agent: shops, orders and payments
A10: 1 | B10: Device merchants, baseline | C10: lakh | D10: =Baseline!H15*100 -> 176.71429 | E10: =Baseline!H16*100 -> 183.28571 | F10: =Baseline!H17*100 -> 189.85714 | G10: =Baseline!H18*100 -> 196.42857 | H10: =Baseline!H19*100 -> 203 | I10: =Baseline!H20*100 -> 209.57143 | J10: =Baseline!H21*100 -> 216.14286 | K10: =Baseline!H22*100 -> 222.71429 | L10: =K10 -> 222.71429
A11: 2 | B11: Grocery and FMCG shops among device merchants | C11: lakh | D11: =D10*Assumptions!$D$10 -> 53.014286 | E11: =E10*Assumptions!$D$10 -> 54.985714 | F11: =F10*Assumptions!$D$10 -> 56.957143 | G11: =G10*Assumptions!$D$10 -> 58.928571 | H11: =H10*Assumptions!$D$10 -> 60.9 | I11: =I10*Assumptions!$D$10 -> 62.871429 | J11: =J10*Assumptions!$D$10 -> 64.842857 | K11: =K10*Assumptions!$D$10 -> 66.814286 | L11: =K11 -> 66.814286
A12: 3 | B12: Restock rollout coverage | C12: % of eligible | D12: =Assumptions!D$79 -> 0.02 | E12: =Assumptions!E$79 -> 0.06 | F12: =Assumptions!F$79 -> 0.12 | G12: =Assumptions!G$79 -> 0.2 | H12: =Assumptions!H$79 -> 0.3 | I12: =Assumptions!I$79 -> 0.4 | J12: =Assumptions!J$79 -> 0.5 | K12: =Assumptions!K$79 -> 0.6 | L12: =K12 -> 0.6
A13: 4 | B13: Active Restock merchants | C13: lakh | D13: =D11*D12*Assumptions!$D$11 -> 0.053014286 | E13: =E11*E12*Assumptions!$D$11 -> 0.16495714 | F13: =F11*F12*Assumptions!$D$11 -> 0.34174286 | G13: =G11*G12*Assumptions!$D$11 -> 0.58928571 | H13: =H11*H12*Assumptions!$D$11 -> 0.9135 | I13: =I11*I12*Assumptions!$D$11 -> 1.2574286 | J13: =J11*J12*Assumptions!$D$11 -> 1.6210714 | K13: =K11*K12*Assumptions!$D$11 -> 2.0044286 | L13: =K13 -> 2.0044286
A14: 5 | B14: Newly active merchants | C14: lakh | D14: =MAX(0,D13-N(C13)) -> 0.053014286 | E14: =MAX(0,E13-N(D13)) -> 0.11194286 | F14: =MAX(0,F13-N(E13)) -> 0.17678571 | G14: =MAX(0,G13-N(F13)) -> 0.24754286 | H14: =MAX(0,H13-N(G13)) -> 0.32421429 | I14: =MAX(0,I13-N(H13)) -> 0.34392857 | J14: =MAX(0,J13-N(I13)) -> 0.36364286 | K14: =MAX(0,K13-N(J13)) -> 0.38335714 | L14: =SUM(D14:K14) -> 2.0044286
A15: 6 | B15: Supplier purchases by active merchants | C15: Rs crore | D15: =D13*Assumptions!$D$12*3/100 -> 238.56429 | E15: =E13*Assumptions!$D$12*3/100 -> 742.30714 | F15: =F13*Assumptions!$D$12*3/100 -> 1537.8429 | G15: =G13*Assumptions!$D$12*3/100 -> 2651.7857 | H15: =H13*Assumptions!$D$12*3/100 -> 4110.75 | I15: =I13*Assumptions!$D$12*3/100 -> 5658.4286 | J15: =J13*Assumptions!$D$12*3/100 -> 7294.8214 | K15: =K13*Assumptions!$D$12*3/100 -> 9019.9286 | L15: =SUM(D15:K15) -> 31254.429
A16: 7 | B16: Ordered through the agent | C16: Rs crore | D16: =D15*Assumptions!$D$13 -> 47.712857 | E16: =E15*Assumptions!$D$13 -> 148.46143 | F16: =F15*Assumptions!$D$13 -> 307.56857 | G16: =G15*Assumptions!$D$13 -> 530.35714 | H16: =H15*Assumptions!$D$13 -> 822.15 | I16: =I15*Assumptions!$D$13 -> 1131.6857 | J16: =J15*Assumptions!$D$13 -> 1458.9643 | K16: =K15*Assumptions!$D$13 -> 1803.9857 | L16: =SUM(D16:K16) -> 6250.8857
A17: 8 | B17: Paid through Paytm | C17: Rs crore | D17: =D16*Assumptions!$D$14 -> 23.856429 | E17: =E16*Assumptions!$D$14 -> 74.230714 | F17: =F16*Assumptions!$D$14 -> 153.78429 | G17: =G16*Assumptions!$D$14 -> 265.17857 | H17: =H16*Assumptions!$D$14 -> 411.075 | I17: =I16*Assumptions!$D$14 -> 565.84286 | J17: =J16*Assumptions!$D$14 -> 729.48214 | K17: =K16*Assumptions!$D$14 -> 901.99286 | L17: =SUM(D17:K17) -> 3125.4429
A18: 9 | B18: GMV: supplier payments new to Paytm | C18: Rs crore | D18: =D17*Assumptions!$D$15 -> 9.5425714 | E18: =E17*Assumptions!$D$15 -> 29.692286 | F18: =F17*Assumptions!$D$15 -> 61.513714 | G18: =G17*Assumptions!$D$15 -> 106.07143 | H18: =H17*Assumptions!$D$15 -> 164.43 | I18: =I17*Assumptions!$D$15 -> 226.33714 | J18: =J17*Assumptions!$D$15 -> 291.79286 | K18: =K17*Assumptions!$D$15 -> 360.79714 | L18: =SUM(D18:K18) -> 1250.1771
A19: 10 | B19: GMV: extra merchant sales on Paytm (fewer stock-outs) | C19: Rs crore | D19: =D13*Assumptions!$D$38*Assumptions!$D$39*3/100 -> 0.79521429 | E19: =E13*Assumptions!$D$38*Assumptions!$D$39*3/100 -> 2.4743571 | F19: =F13*Assumptions!$D$38*Assumptions!$D$39*3/100 -> 5.1261429 | G19: =G13*Assumptions!$D$38*Assumptions!$D$39*3/100 -> 8.8392857 | H19: =H13*Assumptions!$D$38*Assumptions!$D$39*3/100 -> 13.7025 | I19: =I13*Assumptions!$D$38*Assumptions!$D$39*3/100 -> 18.861429 | J19: =J13*Assumptions!$D$38*Assumptions!$D$39*3/100 -> 24.316071 | K19: =K13*Assumptions!$D$38*Assumptions!$D$39*3/100 -> 30.066429 | L19: =SUM(D19:K19) -> 104.18143
B20: Credit router (pay-later per order, plus working-capital loans)
A21: 11 | B21: Pay-later approved (30-day cycles) | C21: Rs crore | D21: =D16*Assumptions!$D$17*Assumptions!$D$18 -> 2.504925 | E21: =E16*Assumptions!$D$17*Assumptions!$D$18 -> 7.794225 | F21: =F16*Assumptions!$D$17*Assumptions!$D$18 -> 16.14735 | G21: =G16*Assumptions!$D$17*Assumptions!$D$18 -> 27.84375 | H21: =H16*Assumptions!$D$17*Assumptions!$D$18 -> 43.162875 | I21: =I16*Assumptions!$D$17*Assumptions!$D$18 -> 59.4135 | J21: =J16*Assumptions!$D$17*Assumptions!$D$18 -> 76.595625 | K21: =K16*Assumptions!$D$17*Assumptions!$D$18 -> 94.70925 | L21: =SUM(D21:K21) -> 328.1715
A22: 12 | B22: via Paytm partner lenders | C22: Rs crore | D22: =D21*Assumptions!$D$19 -> 1.1272163 | E22: =E21*Assumptions!$D$19 -> 3.5074013 | F22: =F21*Assumptions!$D$19 -> 7.2663075 | G22: =G21*Assumptions!$D$19 -> 12.529687 | H22: =H21*Assumptions!$D$19 -> 19.423294 | I22: =I21*Assumptions!$D$19 -> 26.736075 | J22: =J21*Assumptions!$D$19 -> 34.468031 | K22: =K21*Assumptions!$D$19 -> 42.619163 | L22: =SUM(D22:K22) -> 147.67718
A23: 13 | B23: via MUDRA credit line on UPI | C23: Rs crore | D23: =D21*Assumptions!$D$20 -> 0.62623125 | E23: =E21*Assumptions!$D$20 -> 1.9485562 | F23: =F21*Assumptions!$D$20 -> 4.0368375 | G23: =G21*Assumptions!$D$20 -> 6.9609375 | H23: =H21*Assumptions!$D$20 -> 10.790719 | I23: =I21*Assumptions!$D$20 -> 14.853375 | J23: =J21*Assumptions!$D$20 -> 19.148906 | K23: =K21*Assumptions!$D$20 -> 23.677312 | L23: =SUM(D23:K23) -> 82.042875
A24: 14 | B24: via OCEN | C24: Rs crore | D24: =D21*Assumptions!$D$21 -> 0.37573875 | E24: =E21*Assumptions!$D$21 -> 1.1691338 | F24: =F21*Assumptions!$D$21 -> 2.4221025 | G24: =G21*Assumptions!$D$21 -> 4.1765625 | H24: =H21*Assumptions!$D$21 -> 6.4744313 | I24: =I21*Assumptions!$D$21 -> 8.912025 | J24: =J21*Assumptions!$D$21 -> 11.489344 | K24: =K21*Assumptions!$D$21 -> 14.206387 | L24: =SUM(D24:K24) -> 49.225725
A25: 15 | B25: via ONDC Financial Services | C25: Rs crore | D25: =D21*Assumptions!$D$22 -> 0.37573875 | E25: =E21*Assumptions!$D$22 -> 1.1691338 | F25: =F21*Assumptions!$D$22 -> 2.4221025 | G25: =G21*Assumptions!$D$22 -> 4.1765625 | H25: =H21*Assumptions!$D$22 -> 6.4744313 | I25: =I21*Assumptions!$D$22 -> 8.912025 | J25: =J21*Assumptions!$D$22 -> 11.489344 | K25: =K21*Assumptions!$D$22 -> 14.206387 | L25: =SUM(D25:K25) -> 49.225725
A26: 16 | B26: Working-capital loans disbursed | C26: lakh loans | D26: =D13*Assumptions!$D$27/4 -> 0.00066267857 | E26: =E13*Assumptions!$D$27/4 -> 0.0020619643 | F26: =F13*Assumptions!$D$27/4 -> 0.0042717857 | G26: =G13*Assumptions!$D$27/4 -> 0.0073660714 | H26: =H13*Assumptions!$D$27/4 -> 0.01141875 | I26: =I13*Assumptions!$D$27/4 -> 0.015717857 | J26: =J13*Assumptions!$D$27/4 -> 0.020263393 | K26: =K13*Assumptions!$D$27/4 -> 0.025055357 | L26: =SUM(D26:K26) -> 0.086817857
A27: 17 | B27: Working-capital loan value | C27: Rs crore | D27: =D26*Assumptions!$D$28/100 -> 0.66267857 | E27: =E26*Assumptions!$D$28/100 -> 2.0619643 | F27: =F26*Assumptions!$D$28/100 -> 4.2717857 | G27: =G26*Assumptions!$D$28/100 -> 7.3660714 | H27: =H26*Assumptions!$D$28/100 -> 11.41875 | I27: =I26*Assumptions!$D$28/100 -> 15.717857 | J27: =J26*Assumptions!$D$28/100 -> 20.263393 | K27: =K26*Assumptions!$D$28/100 -> 25.055357 | L27: =SUM(D27:K27) -> 86.817857
A28: 18 | B28: Credit routed (pay-later + working capital) | C28: Rs crore | D28: =D21+D27 -> 3.1676036 | E28: =E21+E27 -> 9.8561893 | F28: =F21+F27 -> 20.419136 | G28: =G21+G27 -> 35.209821 | H28: =H21+H27 -> 54.581625 | I28: =I21+I27 -> 75.131357 | J28: =J21+J27 -> 96.859018 | K28: =K21+K27 -> 119.76461 | L28: =SUM(D28:K28) -> 414.98936
B29: Restock Agent: Paytm revenue, costs and contribution
A30: 19 | B30: Revenue: pay-later take | C30: Rs crore | D30: =D22*Assumptions!$D$23+D23*Assumptions!$D$24+D24*Assumptions!$D$25+D25*Assumptions!$D$26 -> 0.0048846037 | E30: =E22*Assumptions!$D$23+E23*Assumptions!$D$24+E24*Assumptions!$D$25+E25*Assumptions!$D$26 -> 0.015198739 | F30: =F22*Assumptions!$D$23+F23*Assumptions!$D$24+F24*Assumptions!$D$25+F25*Assumptions!$D$26 -> 0.031487332 | G30: =G22*Assumptions!$D$23+G23*Assumptions!$D$24+G24*Assumptions!$D$25+G25*Assumptions!$D$26 -> 0.054295312 | H30: =H22*Assumptions!$D$23+H23*Assumptions!$D$24+H24*Assumptions!$D$25+H25*Assumptions!$D$26 -> 0.084167606 | I30: =I22*Assumptions!$D$23+I23*Assumptions!$D$24+I24*Assumptions!$D$25+I25*Assumptions!$D$26 -> 0.11585632 | J30: =J22*Assumptions!$D$23+J23*Assumptions!$D$24+J24*Assumptions!$D$25+J25*Assumptions!$D$26 -> 0.14936147 | K30: =K22*Assumptions!$D$23+K23*Assumptions!$D$24+K24*Assumptions!$D$25+K25*Assumptions!$D$26 -> 0.18468304 | L30: =SUM(D30:K30) -> 0.63993442
A31: 20 | B31: Revenue: working-capital loans | C31: Rs crore | D31: =D27*Assumptions!$D$29 -> 0.013253571 | E31: =E27*Assumptions!$D$29 -> 0.041239286 | F31: =F27*Assumptions!$D$29 -> 0.085435714 | G31: =G27*Assumptions!$D$29 -> 0.14732143 | H31: =H27*Assumptions!$D$29 -> 0.228375 | I31: =I27*Assumptions!$D$29 -> 0.31435714 | J31: =J27*Assumptions!$D$29 -> 0.40526786 | K31: =K27*Assumptions!$D$29 -> 0.50110714 | L31: =SUM(D31:K31) -> 1.7363571
A32: 21 | B32: Revenue: MDR on supplier payments (switch R22) | C32: Rs crore | D32: =D18*Assumptions!$D$34*Assumptions!$D$35*Assumptions!$D$33 -> 0 | E32: =E18*Assumptions!$D$34*Assumptions!$D$35*Assumptions!$D$33 -> 0 | F32: =F18*Assumptions!$D$34*Assumptions!$D$35*Assumptions!$D$33 -> 0 | G32: =G18*Assumptions!$D$34*Assumptions!$D$35*Assumptions!$D$33 -> 0 | H32: =H18*Assumptions!$D$34*Assumptions!$D$35*Assumptions!$D$33 -> 0 | I32: =I18*Assumptions!$D$34*Assumptions!$D$35*Assumptions!$D$33 -> 0 | J32: =J18*Assumptions!$D$34*Assumptions!$D$35*Assumptions!$D$33 -> 0 | K32: =K18*Assumptions!$D$34*Assumptions!$D$35*Assumptions!$D$33 -> 0 | L32: =SUM(D32:K32) -> 0
A33: 22 | B33: Revenue: paid plan | C33: Rs crore | D33: =D13*Assumptions!$D$36*Assumptions!$D$37*3/100 -> 0.0077931 | E33: =E13*Assumptions!$D$36*Assumptions!$D$37*3/100 -> 0.0242487 | F33: =F13*Assumptions!$D$36*Assumptions!$D$37*3/100 -> 0.0502362 | G33: =G13*Assumptions!$D$36*Assumptions!$D$37*3/100 -> 0.086625 | H33: =H13*Assumptions!$D$36*Assumptions!$D$37*3/100 -> 0.1342845 | I33: =I13*Assumptions!$D$36*Assumptions!$D$37*3/100 -> 0.184842 | J33: =J13*Assumptions!$D$36*Assumptions!$D$37*3/100 -> 0.2382975 | K33: =K13*Assumptions!$D$36*Assumptions!$D$37*3/100 -> 0.294651 | L33: =SUM(D33:K33) -> 1.020978
A34: 23 | B34: Revenue: payment margin on extra sales | C34: Rs crore | D34: =D19*Assumptions!$D$6 -> 0.00031808571 | E34: =E19*Assumptions!$D$6 -> 0.00098974286 | F34: =F19*Assumptions!$D$6 -> 0.0020504571 | G34: =G19*Assumptions!$D$6 -> 0.0035357143 | H34: =H19*Assumptions!$D$6 -> 0.005481 | I34: =I19*Assumptions!$D$6 -> 0.0075445714 | J34: =J19*Assumptions!$D$6 -> 0.0097264286 | K34: =K19*Assumptions!$D$6 -> 0.012026571 | L34: =SUM(D34:K34) -> 0.041672571
A35: 24 | B35: Restock revenue | C35: Rs crore | D35: =SUM(D30:D34) -> 0.026249361 | E35: =SUM(E30:E34) -> 0.081676467 | F35: =SUM(F30:F34) -> 0.1692097 | G35: =SUM(G30:G34) -> 0.29177746 | H35: =SUM(H30:H34) -> 0.45230811 | I35: =SUM(I30:I34) -> 0.62260004 | J35: =SUM(J30:J34) -> 0.80265325 | K35: =SUM(K30:K34) -> 0.99246775 | L35: =SUM(D35:K35) -> 3.4389421
A36: 25 | B36: Cost: AI and Intent Guard checks | C36: Rs crore | D36: =D13*Assumptions!$D$41*3/100+D13*Assumptions!$D$36*Assumptions!$D$42*3/100 -> 0.043736786 | E36: =E13*Assumptions!$D$41*3/100+E13*Assumptions!$D$36*Assumptions!$D$42*3/100 -> 0.13608964 | F36: =F13*Assumptions!$D$41*3/100+F13*Assumptions!$D$36*Assumptions!$D$42*3/100 -> 0.28193786 | G36: =G13*Assumptions!$D$41*3/100+G13*Assumptions!$D$36*Assumptions!$D$42*3/100 -> 0.48616071 | H36: =H13*Assumptions!$D$41*3/100+H13*Assumptions!$D$36*Assumptions!$D$42*3/100 -> 0.7536375 | I36: =I13*Assumptions!$D$41*3/100+I13*Assumptions!$D$36*Assumptions!$D$42*3/100 -> 1.0373786 | J36: =J13*Assumptions!$D$41*3/100+J13*Assumptions!$D$36*Assumptions!$D$42*3/100 -> 1.3373839 | K36: =K13*Assumptions!$D$41*3/100+K13*Assumptions!$D$36*Assumptions!$D$42*3/100 -> 1.6536536 | L36: =SUM(D36:K36) -> 5.7299786
A37: 26 | B37: Cost: onboarding newly active merchants | C37: Rs crore | D37: =D14*Assumptions!$D$43/100 -> 0.21205714 | E37: =E14*Assumptions!$D$43/100 -> 0.44777143 | F37: =F14*Assumptions!$D$43/100 -> 0.70714286 | G37: =G14*Assumptions!$D$43/100 -> 0.99017143 | H37: =H14*Assumptions!$D$43/100 -> 1.2968571 | I37: =I14*Assumptions!$D$43/100 -> 1.3757143 | J37: =J14*Assumptions!$D$43/100 -> 1.4545714 | K37: =K14*Assumptions!$D$43/100 -> 1.5334286 | L37: =SUM(D37:K37) -> 8.0177143
A38: 27 | B38: Cost: support | C38: Rs crore | D38: =D13*Assumptions!$D$44*3/100 -> 0.031808571 | E38: =E13*Assumptions!$D$44*3/100 -> 0.098974286 | F38: =F13*Assumptions!$D$44*3/100 -> 0.20504571 | G38: =G13*Assumptions!$D$44*3/100 -> 0.35357143 | H38: =H13*Assumptions!$D$44*3/100 -> 0.5481 | I38: =I13*Assumptions!$D$44*3/100 -> 0.75445714 | J38: =J13*Assumptions!$D$44*3/100 -> 0.97264286 | K38: =K13*Assumptions!$D$44*3/100 -> 1.2026571 | L38: =SUM(D38:K38) -> 4.1672571
A39: 28 | B39: Cost: payment processing | C39: Rs crore | D39: =D18*Assumptions!$D$45 -> 0.0019085143 | E39: =E18*Assumptions!$D$45 -> 0.0059384571 | F39: =F18*Assumptions!$D$45 -> 0.012302743 | G39: =G18*Assumptions!$D$45 -> 0.021214286 | H39: =H18*Assumptions!$D$45 -> 0.032886 | I39: =I18*Assumptions!$D$45 -> 0.045267429 | J39: =J18*Assumptions!$D$45 -> 0.058358571 | K39: =K18*Assumptions!$D$45 -> 0.072159429 | L39: =SUM(D39:K39) -> 0.25003543
A40: 29 | B40: Cost: credit-loss sharing | C40: Rs crore | D40: =D22*Assumptions!$D$30+D27*Assumptions!$D$31 -> 0.012758219 | E40: =E22*Assumptions!$D$30+E27*Assumptions!$D$31 -> 0.039697967 | F40: =F22*Assumptions!$D$30+F27*Assumptions!$D$31 -> 0.082242554 | G40: =G22*Assumptions!$D$30+G27*Assumptions!$D$31 -> 0.14181529 | H40: =H22*Assumptions!$D$30+H27*Assumptions!$D$31 -> 0.21983948 | I40: =I22*Assumptions!$D$30+I27*Assumptions!$D$31 -> 0.30260804 | J40: =J22*Assumptions!$D$30+J27*Assumptions!$D$31 -> 0.39012097 | K40: =K22*Assumptions!$D$30+K27*Assumptions!$D$31 -> 0.48237826 | L40: =SUM(D40:K40) -> 1.6714608
A41: 30 | B41: Restock variable cost | C41: Rs crore | D41: =SUM(D36:D40) -> 0.30226923 | E41: =SUM(E36:E40) -> 0.72847178 | F41: =SUM(F36:F40) -> 1.2886717 | G41: =SUM(G36:G40) -> 1.9929331 | H41: =SUM(H36:H40) -> 2.8513201 | I41: =SUM(I36:I40) -> 3.5154255 | J41: =SUM(J36:J40) -> 4.2130778 | K41: =SUM(K36:K40) -> 4.944277 | L41: =SUM(D41:K41) -> 19.836446
A42: 31 | B42: Restock contribution | C42: Rs crore | D42: =D35-D41 -> -0.27601987 | E42: =E35-E41 -> -0.64679531 | F42: =F35-F41 -> -1.119462 | G42: =G35-G41 -> -1.7011557 | H42: =H35-H41 -> -2.399012 | I42: =I35-I41 -> -2.8928254 | J42: =J35-J41 -> -3.4104245 | K42: =K35-K41 -> -3.9518092 | L42: =SUM(D42:K42) -> -16.397504
...

Sheet Summary
B1: Summary: numbers for the projection slide
B2: All cells link to the Model and Baseline sheets.
B4: A. Base case, quarter by quarter
B5: Metric | C5: Unit | D5: Q4 FY27 | E5: Q1 FY28 | F5: Q2 FY28 | G5: Q3 FY28 | H5: Q4 FY28 | I5: Q1 FY29 | J5: Q2 FY29 | K5: Q3 FY29 | L5: 8-qtr total
B6: Baseline Paytm merchant GMV (FORECAST) | C6: Rs lakh crore | D6: =Model!D172 -> 7.9486905 | E6: =Model!E172 -> 8.2971429 | F6: =Model!F172 -> 8.6455952 | G6: =Model!G172 -> 8.9940476 | H6: =Model!H172 -> 9.3425 | I6: =Model!I172 -> 9.6909524 | J6: =Model!J172 -> 10.039405 | K6: =Model!K172 -> 10.387857 | L6: =Model!L172 -> 73.34619
B7: Incremental GMV from the bundle | C7: Rs crore | D7: =Model!D170 -> 207.88669 | E7: =Model!E170 -> 685.02223 | F7: =Model!F170 -> 1497.0271 | G7: =Model!G170 -> 2663.4943 | H7: =Model!H170 -> 4211.0854 | I7: =Model!I170 -> 5919.9223 | J7: =Model!J170 -> 7803.5397 | K7: =Model!K170 -> 9810.6006 | L7: =Model!L170 -> 32798.578
B8: of which supplier payments new to Paytm (Restock) | C8: Rs crore | D8: =Model!D116 -> 155.862 | E8: =Model!E116 -> 484.974 | F8: =Model!F116 -> 1004.724 | G8: =Model!G116 -> 1732.5 | H8: =Model!H116 -> 2685.69 | I8: =Model!I116 -> 3696.84 | J8: =Model!J116 -> 4765.95 | K8: =Model!K116 -> 5893.02 | L8: =Model!L116 -> 20419.56
B9: of which extra merchant sales (Restock) | C9: Rs crore | D9: =Model!D117 -> 6.7858286 | E9: =Model!E117 -> 21.114514 | F9: =Model!F117 -> 43.743086 | G9: =Model!G117 -> 75.428571 | H9: =Model!H117 -> 116.928 | I9: =Model!I117 -> 160.95086 | J9: =Model!J117 -> 207.49714 | K9: =Model!K117 -> 256.56686 | L9: =Model!L117 -> 889.01486
B10: of which kept during downtime (Care) | C10: Rs crore | D10: =Model!D149 -> 7.0685714 | E10: =Model!E149 -> 21.994286 | F10: =Model!F149 -> 45.565714 | G10: =Model!G149 -> 70.714286 | H10: =Model!H149 -> 97.44 | I10: =Model!I149 -> 117.36 | J10: =Model!J149 -> 138.33143 | K10: =Model!K149 -> 151.44571 | L10: =Model!L149 -> 649.92
B11: of which kept by lower device churn (Care) | C11: Rs crore | D11: =Model!D151 -> 38.170286 | E11: =Model!E151 -> 156.93943 | F11: =Model!F151 -> 402.99429 | G11: =Model!G151 -> 784.85143 | H11: =Model!H151 -> 1311.0274 | I11: =Model!I151 -> 1944.7714 | J11: =Model!J151 -> 2691.7611 | K11: =Model!K151 -> 3509.568 | L11: =Model!L151 -> 10840.083
B12: Uplift vs baseline GMV | C12: % | D12: =Model!D173 -> 0.00026153577 | E12: =Model!E173 -> 0.00082561219 | F12: =Model!F173 -> 0.0017315489 | G12: =Model!G173 -> 0.0029613967 | H12: =Model!H173 -> 0.0045074503 | I12: =Model!I173 -> 0.0061087105 | J12: =Model!J173 -> 0.0077729107 | K12: =Model!K173 -> 0.0094442968 | L12: =Model!L173 -> 0.0044717494
B13: Active Restock merchants | C13: lakh | D13: =Model!D111 -> 0.14137143 | E13: =Model!E111 -> 0.43988571 | F13: =Model!F111 -> 0.91131429 | G13: =Model!G111 -> 1.5714286 | H13: =Model!H111 -> 2.436 | I13: =Model!I111 -> 3.3531429 | J13: =Model!J111 -> 4.3228571 | K13: =Model!K111 -> 5.3451429 | L13: =Model!L111 -> 5.3451429
B14: Devices covered by Soundbox Care | C14: lakh | D14: =Model!D144 -> 8.8357143 | E14: =Model!E144 -> 27.492857 | F14: =Model!F144 -> 56.957143 | G14: =Model!G144 -> 88.392857 | H14: =Model!H144 -> 121.8 | I14: =Model!I144 -> 146.7 | J14: =Model!J144 -> 172.91429 | K14: =Model!K144 -> 189.30714 | L14: =Model!L144 -> 189.30714
B15: Credit routed (pay-later + working capital) | C15: Rs crore | D15: =Model!D126 -> 51.688929 | E15: =Model!E126 -> 160.83321 | F15: =Model!F126 -> 333.19929 | G15: =Model!G126 -> 574.55357 | H15: =Model!H126 -> 890.6625 | I15: =Model!I126 -> 1225.9929 | J15: =Model!J126 -> 1580.5446 | K15: =Model!K126 -> 1954.3179 | L15: =Model!L126 -> 6771.7929
B16: Revenue | C16: Rs crore | D16: =Model!D174 -> 0.56767874 | E16: =Model!E174 -> 1.8388901 | F16: =Model!F174 -> 3.9575788 | G16: =Model!G174 -> 6.9920231 | H16: =Model!H174 -> 11.013329 | I16: =Model!I174 -> 15.419372 | J16: =Model!J174 -> 20.224083 | K16: =Model!K174 -> 25.343284 | L16: =Model!L174 -> 85.356238
B17: of which credit (pay-later take + working-capital loans) | C17: Rs crore | D17: =Model!D128+Model!D129 -> 0.31212161 | E17: =Model!E128+Model!E129 -> 0.97118518 | F17: =Model!F128+Model!F129 -> 2.0120111 | G17: =Model!G128+Model!G129 -> 3.4694196 | H17: =Model!H128+Model!H129 -> 5.3782312 | I17: =Model!I128+Model!I129 -> 7.4031107 | J17: =Model!J128+Model!J129 -> 9.544058 | K17: =Model!K128+Model!K129 -> 11.801073 | L17: =Model!L128+Model!L129 -> 40.891211
B18: of which MDR on supplier payments | C18: Rs crore | D18: =Model!D130 -> 0.0935172 | E18: =Model!E130 -> 0.2909844 | F18: =Model!F130 -> 0.6028344 | G18: =Model!G130 -> 1.0395 | H18: =Model!H130 -> 1.611414 | I18: =Model!I130 -> 2.218104 | J18: =Model!J130 -> 2.85957 | K18: =Model!K130 -> 3.535812 | L18: =Model!L130 -> 12.251736
B19: of which paid plan | C19: Rs crore | D19: =Model!D131 -> 0.083974629 | E19: =Model!E131 -> 0.26129211 | F19: =Model!F131 -> 0.54132069 | G19: =Model!G131 -> 0.93342857 | H19: =Model!H131 -> 1.446984 | I19: =Model!I131 -> 1.9917669 | J19: =Model!J131 -> 2.5677771 | K19: =Model!K131 -> 3.1750149 | L19: =Model!L131 -> 11.001559
B20: of which device subscriptions kept (Care) | C20: Rs crore | D20: =Model!D152 -> 0.057255429 | E20: =Model!E152 -> 0.23540914 | F20: =Model!F152 -> 0.60449143 | G20: =Model!G152 -> 1.1772771 | H20: =Model!H152 -> 1.9665411 | I20: =Model!I152 -> 2.9171571 | J20: =Model!J152 -> 4.0376417 | K20: =Model!K152 -> 5.264352 | L20: =Model!L152 -> 16.260125
B21: Variable cost | C21: Rs crore | D21: =Model!D175 -> 0.89705915 | E21: =Model!E175 -> 2.437825 | F21: =Model!F175 -> 4.6829451 | G21: =Model!G175 -> 7.3002098 | H21: =Model!H175 -> 10.310838 | I21: =Model!I175 -> 12.672197 | J21: =Model!J175 -> 15.156856 | K21: =Model!K175 -> 17.319389 | L21: =Model!L175 -> 70.777319
B22: Avoided costs (Care: field visits, replacements) | C22: Rs crore | D22: =Model!D176 -> 0.88798929 | E22: =Model!E176 -> 2.7630321 | F22: =Model!F176 -> 5.7241929 | G22: =Model!G176 -> 8.8834821 | H22: =Model!H176 -> 12.2409 | I22: =Model!I176 -> 14.74335 | J22: =Model!J176 -> 17.377886 | K22: =Model!K176 -> 19.025368 | L22: =Model!L176 -> 81.6462
B23: Contribution to Paytm | C23: Rs crore | D23: =Model!D177 -> 0.55860888 | E23: =Model!E177 -> 2.1640973 | F23: =Model!F177 -> 4.9988266 | G23: =Model!G177 -> 8.5752954 | H23: =Model!H177 -> 12.94339 | I23: =Model!I177 -> 17.490525 | J23: =Model!J177 -> 22.445112 | K23: =Model!K177 -> 27.049264 | L23: =Model!L177 -> 96.22512
B24: of which Restock Agent | C24: Rs crore | D24: =Model!D140 -> -0.051302808 | E24: =Model!E140 -> 0.19379679 | F24: =Model!F140 -> 0.76900403 | G24: =Model!G140 -> 1.7080241 | H24: =Model!H140 -> 3.0445623 | I24: =Model!I140 -> 4.8731654 | J24: =Model!J140 -> 6.8141193 | K24: =Model!K140 -> 8.8674239 | L24: =Model!L140 -> 26.218793
B25: of which Soundbox Care | C25: Rs crore | D25: =Model!D159 -> 0.60991169 | E25: =Model!E159 -> 1.9703005 | F25: =Model!F159 -> 4.2298226 | G25: =Model!G159 -> 6.8672713 | H25: =Model!H159 -> 9.8988281 | I25: =Model!I159 -> 12.61736 | J25: =Model!J159 -> 15.630993 | K25: =Model!K159 -> 18.18184 | L25: =Model!L159 -> 70.006327
B26: Contribution as % of revenue plus avoided costs | C26: % | D26: =Model!D179 -> 0.38374744 | E26: =Model!E179 -> 0.47025942 | F26: =Model!F179 -> 0.51631321 | G26: =Model!G179 -> 0.5401589 | H26: =Model!H179 -> 0.55660373 | I26: =Model!I179 -> 0.57987225 | J26: =Model!J179 -> 0.59691323 | K26: =Model!K179 -> 0.60964808 | L26: =Model!L179 -> 0.57618991
B27: Restock margin on Restock revenue | C27: % | D27: =Model!D180 -> -0.10420458 | E27: =Model!E180 -> 0.12650685 | F27: =Model!F180 -> 0.242308 | G27: =Model!G180 -> 0.31210927 | H27: =Model!H180 -> 0.35888466 | I27: =Model!I180 -> 0.41731732 | J27: =Model!J180 -> 0.45263295 | K27: =Model!K180 -> 0.47637117 | L27: =Model!L180 -> 0.40649221
B28: Care: avoided costs plus revenue per Rs 1 of Care cost | C28: x | D28: =Model!D181 -> 2.7257 | E28: =Model!E181 -> 2.7916476 | F28: =Model!F181 -> 2.8565813 | G28: =Model!G181 -> 2.9422585 | H28: =Model!H181 -> 3.0317792 | I28: =Model!I181 -> 3.1501976 | J28: =Model!J181 -> 3.2599337 | K28: =Model!K181 -> 3.4011032 | L28: =Model!L181 -> 3.154306
B29: Quarterly contribution vs Q1 FY27 EBITDA (Rs 203 crore) | C29: % | D29: =Model!D184 -> 0.0027517679 | E29: =Model!E184 -> 0.010660578 | F29: =Model!F184 -> 0.024624762 | G29: =Model!G184 -> 0.042242834 | H29: =Model!H184 -> 0.063760544 | I29: =Model!I184 -> 0.086160222 | J29: =Model!J184 -> 0.11056706 | K29: =Model!K184 -> 0.1332476
B30: Merchant money protected by Intent Guard | C30: Rs crore | D30: =Model!D141 -> 0.7422 | E30: =Model!E141 -> 2.3094 | F30: =Model!F141 -> 4.7844 | G30: =Model!G141 -> 8.25 | H30: =Model!H141 -> 12.789 | I30: =Model!I141 -> 17.604 | J30: =Model!J141 -> 22.695 | K30: =Model!K141 -> 28.062 | L30: =Model!L141 -> 97.236
B32: B. Scenarios side by side
B33: Metric | C33: Unit | D33: Bear | E33: Base | F33: Bull
B34: Incremental GMV, 8 quarters | C34: Rs crore | D34: =Model!L72 -> 6006.46 | E34: =Model!L170 -> 32798.578 | F34: =Model!L268 -> 143347.9
B35: Incremental GMV in Q3 FY29 | C35: Rs crore | D35: =Model!K72 -> 1884.7348 | E35: =Model!K170 -> 9810.6006 | F35: =Model!K268 -> 42038.146
B36: Uplift vs baseline GMV at Q3 FY29 | C36: % | D36: =Model!K75 -> 0.0018143634 | E36: =Model!K173 -> 0.0094442968 | F36: =Model!K271 -> 0.040468544
B37: Contribution to Paytm, 8 quarters | C37: Rs crore | D37: =Model!L79 -> -27.416841 | E37: =Model!L177 -> 96.22512 | F37: =Model!L275 -> 601.42431
B38: of which Restock Agent | C38: Rs crore | D38: =Model!L42 -> -16.397504 | E38: =Model!L140 -> 26.218793 | F38: =Model!L238 -> 443.52232
B39: of which Soundbox Care | C39: Rs crore | D39: =Model!L61 -> -11.019337 | E39: =Model!L159 -> 70.006327 | F39: =Model!L257 -> 157.90199
B40: Contribution in Q3 FY29 | C40: Rs crore | D40: =Model!K79 -> -5.6999005 | E40: =Model!K177 -> 27.049264 | F40: =Model!K275 -> 169.50298
B41: Q3 FY29 contribution vs Q1 FY27 EBITDA | C41: % | D41: =Model!K86 -> -0.028078328 | E41: =Model!K184 -> 0.1332476 | F41: =Model!K282 -> 0.83499007
B42: Contribution as % of revenue plus avoided costs, 8 quarters | C42: % | D42: =Model!L81 -> -0.51390898 | E42: =Model!L179 -> 0.57618991 | F42: =Model!L277 -> 0.91070392
...

Sheet Sources
A1: Sources
A3: ID | B3: What it supports | C3: Link
A4: S1 | B4: Paytm Q1 FY27 earnings release (agent datapack): GMV Jun-25 / Mar-26 / Jun-26, subscription merchants, net payment revenue 8.4 bps, processing margin >4 bps, Marketing Services Rs 239 crore, cashback Rs 90 crore, registered merchants | C4: https://paytm.com/document/ir/financial-results/fy2026-27/Paytm_Q1_FY27_Agent_Datapack.md
A5: S2 | B5: Q2 FY26 (Sep-25): GMV Rs 5.67 lakh crore, subscriptions 1.37 crore | C5: https://ianslive.in/paytms-profitability-improves-to-rs-211-crore-in-q2-revenue-up-24-pc--20251104222037
A6: S3 | B6: Q3 FY26 (Dec-25): GMV Rs 6.2 lakh crore | C6: https://www.businesstoday.in/amp/latest/corporate/story/paytms-q3-net-profit-jumps-to-rs225-crore-on-upi-surge-and-merchant-services-boost-513573-2026-01-29
A7: S4 | B7: Q4 FY25 (Mar-25): GMV Rs 5.1 lakh crore, subscriptions 1.24 crore | C7: https://www.business-standard.com/companies/quarterly-results/one-97-communication-paytm-q4-fy25-result-loss-profit-revenue-stock-option-125050601030_1.html
A8: S5 | B8: Q3 FY25 (Dec-24): GMV Rs 5.0 lakh crore, up 13% QoQ from Rs 4.5 lakh crore; subscriptions 1.17 crore after 5 lakh QoQ additions | C8: https://inc42.com/?p=495669
A9: S6 | B9: Q3 FY26 (Dec-25): subscription merchants 1.44 crore | C9: https://alphastreet.com/india/symbol/PAYTM
A10: S7 | B10: Soundbox rental Rs 125-150 a month (BofA merchant checks in Mumbai) | C10: https://www.outlookbusiness.com/amp/story/enterprise/bofa-research-paytm-soundbox-first-to-bring-audio-based-payments-confirmations-dominates-the-market-6795
A11: S8 | B11: Paytm subscription revenue ~Rs 90 per device a month (Q4 FY24) | C11: https://www.medianama.com/2024/10/223-paytm-to-monetize-soundbox-ads-in-partnership-with-meesho-a-shift-away-from-core-payments-business/
A12: S9 | B12: Merchants often keep separate soundboxes for PhonePe, Paytm and Google Pay | C12: https://inc42.com/buzz/upi-transactions-jump-3-8-mom-in-may-cross-23-bn-mark/
A13: S10 | B13: Paytm Q1 FY27 results: revenue Rs 2,448 crore, contribution profit Rs 1,350 crore at 55%, EBITDA Rs 203 crore, PAT Rs 220 crore, financial services Rs 814 crore (+45%), 1.57 crore device merchants, online payment aggregator licence and online merchant momentum | C13: https://paytm.com/blog/investor-relations/paytm-q1-fy27-results-revenue-grows-28-to-2448-crore-highest-ever-quarterly-ebitda-at-203-crore/
A14: S11 | B14: Paytm merchant loans: up to Rs 10 lakh, 6-24 months, daily instalments; over 50% of merchant-loan value to repeat borrowers (Paytm-Piramal release, Aug 2022) | C14: https://bseindia.com/xml-data/corpfiling/AttachHis/01144943-65d3-465d-a4cc-f0556ff55ec5.pdf
... A31: S28 | B31: NPCI agentic payments on UPI (reported Unified Agent Protocol), Sep 2026 | C31: https://inc42.com/buzz/npci-to-launch-agentic-payments-on-upi-report/
